[2020-10-27 10:00:57,903] [basehttp.py:124] [basehttp:log_message] [INFO]- "GET /user/login HTTP/1.1" 200 4225
[2020-10-27 10:00:57,980] [basehttp.py:124] [basehttp:log_message] [INFO]- "GET /user/draw HTTP/1.1" 200 2492
[2020-10-27 10:00:58,098] [base.py:93] [base:get_response] [WARNING]- Not Found: /favicon.ico
[2020-10-27 10:00:58,099] [basehttp.py:124] [basehttp:log_message] [WARNING]- "GET /favicon.ico HTTP/1.1" 404 2191
[2020-10-27 10:01:08,879] [basehttp.py:124] [basehttp:log_message] [INFO]- "POST /user/login HTTP/1.1" 302 0
[2020-10-27 10:01:08,897] [views.py:25] [views:index] [INFO]- 缓存中的key为：4140719817f811eb80dd5800e3fb0696----浏览器中的key为:4140719817f811eb80dd5800e3fb0696
[2020-10-27 10:01:09,078] [basehttp.py:124] [basehttp:log_message] [INFO]- "GET /novels/index HTTP/1.1" 200 17973
[2020-10-27 10:01:09,114] [basehttp.py:124] [basehttp:log_message] [INFO]- "GET /static/media/type/58950l.jpg HTTP/1.1" 304 0
[2020-10-27 10:01:09,116] [basehttp.py:124] [basehttp:log_message] [INFO]- "GET /static/media/type/58950l_5kfSspN.jpg HTTP/1.1" 304 0
[2020-10-27 10:01:09,141] [basehttp.py:124] [basehttp:log_message] [INFO]- "GET /static/media/type/58950l_O9lXQZR.jpg HTTP/1.1" 304 0
[2020-10-27 10:01:09,146] [basehttp.py:124] [basehttp:log_message] [INFO]- "GET /static/media/type/57304l.jpg HTTP/1.1" 304 0
[2020-10-27 10:01:09,156] [basehttp.py:124] [basehttp:log_message] [INFO]- "GET /static/media/type/57840l.jpg HTTP/1.1" 304 0
[2020-10-27 10:01:09,161] [basehttp.py:124] [basehttp:log_message] [INFO]- "GET /static/media/type/59178l.jpg HTTP/1.1" 304 0
[2020-10-27 10:01:09,164] [basehttp.py:124] [basehttp:log_message] [INFO]- "GET /static/media/banner/8797s.jpg HTTP/1.1" 304 0
[2020-10-27 10:01:09,165] [basehttp.py:124] [basehttp:log_message] [INFO]- "GET /static/media/banner/57304l.jpg HTTP/1.1" 304 0
[2020-10-27 10:01:11,887] [views.py:25] [views:index] [INFO]- 缓存中的key为：4140719817f811eb80dd5800e3fb0696----浏览器中的key为:4140719817f811eb80dd5800e3fb0696
[2020-10-27 10:01:11,958] [basehttp.py:124] [basehttp:log_message] [INFO]- "GET /novels/index HTTP/1.1" 200 17973
[2020-10-27 10:01:15,240] [basehttp.py:124] [basehttp:log_message] [INFO]- "GET /novels/detail/11111111 HTTP/1.1" 200 7027
[2020-10-27 10:01:15,255] [basehttp.py:124] [basehttp:log_message] [INFO]- "GET /static/media/novels/8797s.jpg HTTP/1.1" 304 0
[2020-10-27 10:03:38,813] [basehttp.py:124] [basehttp:log_message] [INFO]- "GET /novels/detail/1111 HTTP/1.1" 200 7342
[2020-10-27 10:03:38,831] [basehttp.py:124] [basehttp:log_message] [INFO]- "GET /static/media/novels/58950l.jpg HTTP/1.1" 304 0
[2020-10-27 10:03:40,896] [basehttp.py:124] [basehttp:log_message] [INFO]- "GET /novels/novelbody/44444444 HTTP/1.1" 200 12560
[2020-10-27 10:32:16,844] [basehttp.py:124] [basehttp:log_message] [INFO]- "GET /novels/detail/12121456 HTTP/1.1" 200 7257
[2020-10-27 10:32:16,871] [basehttp.py:124] [basehttp:log_message] [INFO]- "GET /static/media/novels/57304l.jpg HTTP/1.1" 304 0
[2020-10-27 10:32:22,375] [views.py:25] [views:index] [INFO]- 缓存中的key为：None----浏览器中的key为:4140719817f811eb80dd5800e3fb0696
[2020-10-27 10:32:22,385] [basehttp.py:124] [basehttp:log_message] [INFO]- "GET /novels/index HTTP/1.1" 302 0
[2020-10-27 10:32:22,394] [basehttp.py:124] [basehttp:log_message] [INFO]- "GET /user/login HTTP/1.1" 200 4225
[2020-10-27 10:32:22,427] [basehttp.py:124] [basehttp:log_message] [INFO]- "GET /user/draw HTTP/1.1" 200 2618
[2020-10-27 10:32:32,155] [basehttp.py:124] [basehttp:log_message] [INFO]- "POST /user/login HTTP/1.1" 302 0
[2020-10-27 10:32:32,176] [views.py:25] [views:index] [INFO]- 缓存中的key为：a47f6aa617fc11eb89515800e3fb0696----浏览器中的key为:a47f6aa617fc11eb89515800e3fb0696
[2020-10-27 10:32:32,239] [basehttp.py:124] [basehttp:log_message] [INFO]- "GET /novels/index HTTP/1.1" 200 17973
[2020-10-27 10:34:43,057] [views.py:25] [views:index] [INFO]- 缓存中的key为：a47f6aa617fc11eb89515800e3fb0696----浏览器中的key为:a47f6aa617fc11eb89515800e3fb0696
[2020-10-27 10:34:43,123] [basehttp.py:124] [basehttp:log_message] [INFO]- "GET /novels/index HTTP/1.1" 200 17942
[2020-10-27 10:34:44,209] [basehttp.py:124] [basehttp:log_message] [INFO]- "GET /novels/detail/11111111 HTTP/1.1" 200 7462
[2020-10-27 10:34:54,525] [basehttp.py:124] [basehttp:log_message] [INFO]- "GET /novels/detail/121212121212 HTTP/1.1" 200 8135
[2020-10-27 10:34:57,608] [exception.py:118] [exception:handle_uncaught_exception] [ERROR]- Internal Server Error: /novels/novelbody/232311111
Traceback (most recent call last):
  File "D:\Envs\Django2020\lib\site-packages\django\core\handlers\exception.py", line 35, in inner
    response = get_response(request)
  File "D:\Envs\Django2020\lib\site-packages\django\core\handlers\base.py", line 128, in _get_response
    response = self.process_exception_by_middleware(e, request)
  File "D:\Envs\Django2020\lib\site-packages\django\core\handlers\base.py", line 126, in _get_response
    response = wrapped_callback(request, *callback_args, **callback_kwargs)
  File "C:\Users\xinxi\PycharmProjects\Qinxiangshuge\novels\views.py", line 82, in novel_body
    with open(file_name, encoding='utf-8') as file_obj:
FileNotFoundError: [Errno 2] No such file or directory: 'D:\\novels\\232311111.txt'
[2020-10-27 10:34:57,657] [basehttp.py:124] [basehttp:log_message] [ERROR]- "GET /novels/novelbody/232311111 HTTP/1.1" 500 75019
[2020-10-27 10:35:03,308] [basehttp.py:124] [basehttp:log_message] [INFO]- "GET /novels/novelbody/111111 HTTP/1.1" 200 12938
[2020-10-27 10:36:39,197] [basehttp.py:124] [basehttp:log_message] [INFO]- "GET /novels/show_bookrack HTTP/1.1" 200 8776
[2020-10-27 10:36:59,092] [views.py:25] [views:index] [INFO]- 缓存中的key为：a47f6aa617fc11eb89515800e3fb0696----浏览器中的key为:a47f6aa617fc11eb89515800e3fb0696
[2020-10-27 10:36:59,224] [basehttp.py:124] [basehttp:log_message] [INFO]- "GET /novels/index HTTP/1.1" 200 17941
[2020-10-27 10:37:09,453] [basehttp.py:124] [basehttp:log_message] [INFO]- "GET /novels/detail/1111 HTTP/1.1" 200 7806
[2020-10-27 10:37:21,828] [basehttp.py:124] [basehttp:log_message] [INFO]- "POST /novels/search HTTP/1.1" 200 7354
[2020-10-27 10:38:13,724] [basehttp.py:124] [basehttp:log_message] [INFO]- "GET /novels/show_bookrack HTTP/1.1" 200 7440
[2020-10-27 10:38:32,174] [basehttp.py:124] [basehttp:log_message] [INFO]- "GET /novels/show_bookrack HTTP/1.1" 200 7455
[2020-10-27 10:38:33,845] [basehttp.py:124] [basehttp:log_message] [INFO]- "GET /novels/show_bookrack HTTP/1.1" 200 7455
[2020-10-27 10:39:52,621] [basehttp.py:124] [basehttp:log_message] [INFO]- "GET /novels/show_bookrack HTTP/1.1" 200 7455
[2020-10-27 10:39:57,093] [basehttp.py:124] [basehttp:log_message] [INFO]- "GET /novels/show_bookrack HTTP/1.1" 200 7505
[2020-10-27 10:39:57,690] [basehttp.py:124] [basehttp:log_message] [INFO]- "GET /novels/show_bookrack HTTP/1.1" 200 7505
[2020-10-27 10:39:57,955] [basehttp.py:124] [basehttp:log_message] [INFO]- "GET /novels/show_bookrack HTTP/1.1" 200 7505
[2020-10-27 10:39:58,191] [basehttp.py:124] [basehttp:log_message] [INFO]- "GET /novels/show_bookrack HTTP/1.1" 200 7505
[2020-10-27 10:40:14,218] [basehttp.py:124] [basehttp:log_message] [INFO]- "GET /novels/show_bookrack HTTP/1.1" 200 7520
[2020-10-27 10:40:41,049] [basehttp.py:124] [basehttp:log_message] [INFO]- "GET /novels/show_bookrack HTTP/1.1" 200 7521
[2020-10-27 10:40:43,155] [basehttp.py:124] [basehttp:log_message] [INFO]- "GET /novels/show_bookrack HTTP/1.1" 200 7521
[2020-10-27 10:40:44,620] [basehttp.py:124] [basehttp:log_message] [INFO]- "GET /novels/show_bookrack HTTP/1.1" 200 7521
[2020-10-27 10:40:45,445] [basehttp.py:124] [basehttp:log_message] [INFO]- "GET /novels/show_bookrack HTTP/1.1" 200 7521
[2020-10-27 10:41:05,096] [basehttp.py:124] [basehttp:log_message] [INFO]- "GET /novels/show_bookrack HTTP/1.1" 200 7495
[2020-10-27 10:41:16,831] [basehttp.py:124] [basehttp:log_message] [INFO]- "GET /novels/show_bookrack HTTP/1.1" 200 7491
[2020-10-27 10:41:17,463] [basehttp.py:124] [basehttp:log_message] [INFO]- "GET /novels/show_bookrack HTTP/1.1" 200 7491
[2020-10-27 10:41:17,682] [basehttp.py:124] [basehttp:log_message] [INFO]- "GET /novels/show_bookrack HTTP/1.1" 200 7491
[2020-10-27 10:41:17,913] [basehttp.py:124] [basehttp:log_message] [INFO]- "GET /novels/show_bookrack HTTP/1.1" 200 7491
[2020-10-27 10:41:18,100] [basehttp.py:124] [basehttp:log_message] [INFO]- "GET /novels/show_bookrack HTTP/1.1" 200 7491
[2020-10-27 10:42:42,003] [basehttp.py:124] [basehttp:log_message] [INFO]- "GET /novels/show_bookrack HTTP/1.1" 200 7469
[2020-10-27 13:29:39,419] [basehttp.py:124] [basehttp:log_message] [INFO]- "GET /novels/show_bookrack HTTP/1.1" 200 7469
[2020-10-27 13:42:13,736] [basehttp.py:124] [basehttp:log_message] [INFO]- "GET /novels/show_bookrack HTTP/1.1" 200 7469
[2020-10-27 14:16:37,326] [views.py:25] [views:index] [INFO]- 缓存中的key为：None----浏览器中的key为:a47f6aa617fc11eb89515800e3fb0696
[2020-10-27 14:16:37,343] [basehttp.py:124] [basehttp:log_message] [INFO]- "GET /novels/index HTTP/1.1" 302 0
[2020-10-27 14:16:37,361] [basehttp.py:124] [basehttp:log_message] [INFO]- "GET /user/login HTTP/1.1" 200 4689
[2020-10-27 14:16:37,395] [basehttp.py:124] [basehttp:log_message] [INFO]- "GET /user/draw HTTP/1.1" 200 2945
[2020-10-27 14:16:46,339] [basehttp.py:124] [basehttp:log_message] [INFO]- "POST /user/login HTTP/1.1" 302 0
[2020-10-27 14:16:46,358] [views.py:25] [views:index] [INFO]- 缓存中的key为：f8485c76181b11eba42f5800e3fb0696----浏览器中的key为:f8485c76181b11eba42f5800e3fb0696
[2020-10-27 14:16:46,522] [basehttp.py:124] [basehttp:log_message] [INFO]- "GET /novels/index HTTP/1.1" 200 17941
[2020-10-27 14:18:08,228] [basehttp.py:124] [basehttp:log_message] [INFO]- "GET /user/login HTTP/1.1" 200 4227
[2020-10-27 14:18:08,277] [basehttp.py:124] [basehttp:log_message] [INFO]- "GET /user/draw HTTP/1.1" 200 2828
[2020-10-27 14:18:09,902] [basehttp.py:124] [basehttp:log_message] [INFO]- "GET /user/login HTTP/1.1" 200 4227
[2020-10-27 14:18:09,944] [basehttp.py:124] [basehttp:log_message] [INFO]- "GET /user/draw HTTP/1.1" 200 2580
[2020-10-27 14:18:15,491] [basehttp.py:124] [basehttp:log_message] [INFO]- "GET /user/draw?ran=0.7924715788613439 HTTP/1.1" 200 2752
[2020-10-27 14:18:21,556] [basehttp.py:124] [basehttp:log_message] [INFO]- "POST /user/login HTTP/1.1" 200 4329
[2020-10-27 14:18:21,592] [basehttp.py:124] [basehttp:log_message] [INFO]- "GET /user/draw HTTP/1.1" 200 2557
[2020-10-27 14:19:17,165] [basehttp.py:124] [basehttp:log_message] [INFO]- "POST /user/login HTTP/1.1" 302 0
[2020-10-27 14:19:17,177] [views.py:25] [views:index] [INFO]- 缓存中的key为：2f712a18181c11ebaabc5800e3fb0696----浏览器中的key为:2f712a18181c11ebaabc5800e3fb0696
[2020-10-27 14:19:17,242] [basehttp.py:124] [basehttp:log_message] [INFO]- "GET /novels/index HTTP/1.1" 200 17943
[2020-10-27 14:19:32,561] [basehttp.py:124] [basehttp:log_message] [INFO]- "GET /novels/detail/1111 HTTP/1.1" 200 8492
[2020-10-27 14:28:40,828] [basehttp.py:124] [basehttp:log_message] [INFO]- "GET /novels/detail/1111 HTTP/1.1" 200 8492
[2020-10-27 14:31:29,695] [basehttp.py:124] [basehttp:log_message] [INFO]- "GET /novels/detail/1111 HTTP/1.1" 200 8332
[2020-10-27 14:31:29,735] [basehttp.py:124] [basehttp:log_message] [INFO]- "GET /static/media/novels/58950l.jpg HTTP/1.1" 200 335654
[2020-10-27 14:31:58,488] [basehttp.py:124] [basehttp:log_message] [INFO]- "GET /novels/detail/1111 HTTP/1.1" 200 8314
[2020-10-27 14:31:58,516] [basehttp.py:124] [basehttp:log_message] [INFO]- "GET /static/media/novels/58950l.jpg HTTP/1.1" 200 335654
[2020-10-27 14:33:09,900] [basehttp.py:124] [basehttp:log_message] [INFO]- "GET /novels/detail/1111 HTTP/1.1" 200 8314
[2020-10-27 14:33:09,928] [basehttp.py:124] [basehttp:log_message] [INFO]- "GET /static/media/novels/58950l.jpg HTTP/1.1" 200 335654
[2020-10-27 14:34:21,883] [exception.py:118] [exception:handle_uncaught_exception] [ERROR]- Internal Server Error: /novels/show_bookrack
Traceback (most recent call last):
  File "D:\Envs\Django2020\lib\site-packages\django\core\handlers\exception.py", line 35, in inner
    response = get_response(request)
  File "D:\Envs\Django2020\lib\site-packages\django\core\handlers\base.py", line 128, in _get_response
    response = self.process_exception_by_middleware(e, request)
  File "D:\Envs\Django2020\lib\site-packages\django\core\handlers\base.py", line 126, in _get_response
    response = wrapped_callback(request, *callback_args, **callback_kwargs)
  File "C:\Users\xinxi\PycharmProjects\Qinxiangshuge\novels\views.py", line 101, in show_bookrack
    mybookrack = MyBookrack.objects.filter(user=request.user)
  File "D:\Envs\Django2020\lib\site-packages\django\db\models\manager.py", line 82, in manager_method
    return getattr(self.get_queryset(), name)(*args, **kwargs)
  File "D:\Envs\Django2020\lib\site-packages\django\db\models\query.py", line 836, in filter
    return self._filter_or_exclude(False, *args, **kwargs)
  File "D:\Envs\Django2020\lib\site-packages\django\db\models\query.py", line 854, in _filter_or_exclude
    clone.query.add_q(Q(*args, **kwargs))
  File "D:\Envs\Django2020\lib\site-packages\django\db\models\sql\query.py", line 1252, in add_q
    clause, _ = self._add_q(q_object, self.used_aliases)
  File "D:\Envs\Django2020\lib\site-packages\django\db\models\sql\query.py", line 1276, in _add_q
    split_subq=split_subq,
  File "D:\Envs\Django2020\lib\site-packages\django\db\models\sql\query.py", line 1186, in build_filter
    self.check_related_objects(join_info.final_field, value, join_info.opts)
  File "D:\Envs\Django2020\lib\site-packages\django\db\models\sql\query.py", line 1052, in check_related_objects
    for v in value:
  File "D:\Envs\Django2020\lib\site-packages\django\utils\functional.py", line 216, in inner
    return func(self._wrapped, *args)
TypeError: 'AnonymousUser' object is not iterable
[2020-10-27 14:34:21,985] [basehttp.py:124] [basehttp:log_message] [ERROR]- "GET /novels/show_bookrack HTTP/1.1" 500 112847
[2020-10-27 14:34:24,353] [exception.py:118] [exception:handle_uncaught_exception] [ERROR]- Internal Server Error: /novels/show_bookrack
Traceback (most recent call last):
  File "D:\Envs\Django2020\lib\site-packages\django\core\handlers\exception.py", line 35, in inner
    response = get_response(request)
  File "D:\Envs\Django2020\lib\site-packages\django\core\handlers\base.py", line 128, in _get_response
    response = self.process_exception_by_middleware(e, request)
  File "D:\Envs\Django2020\lib\site-packages\django\core\handlers\base.py", line 126, in _get_response
    response = wrapped_callback(request, *callback_args, **callback_kwargs)
  File "C:\Users\xinxi\PycharmProjects\Qinxiangshuge\novels\views.py", line 101, in show_bookrack
    mybookrack = MyBookrack.objects.filter(user=request.user)
  File "D:\Envs\Django2020\lib\site-packages\django\db\models\manager.py", line 82, in manager_method
    return getattr(self.get_queryset(), name)(*args, **kwargs)
  File "D:\Envs\Django2020\lib\site-packages\django\db\models\query.py", line 836, in filter
    return self._filter_or_exclude(False, *args, **kwargs)
  File "D:\Envs\Django2020\lib\site-packages\django\db\models\query.py", line 854, in _filter_or_exclude
    clone.query.add_q(Q(*args, **kwargs))
  File "D:\Envs\Django2020\lib\site-packages\django\db\models\sql\query.py", line 1252, in add_q
    clause, _ = self._add_q(q_object, self.used_aliases)
  File "D:\Envs\Django2020\lib\site-packages\django\db\models\sql\query.py", line 1276, in _add_q
    split_subq=split_subq,
  File "D:\Envs\Django2020\lib\site-packages\django\db\models\sql\query.py", line 1186, in build_filter
    self.check_related_objects(join_info.final_field, value, join_info.opts)
  File "D:\Envs\Django2020\lib\site-packages\django\db\models\sql\query.py", line 1052, in check_related_objects
    for v in value:
  File "D:\Envs\Django2020\lib\site-packages\django\utils\functional.py", line 216, in inner
    return func(self._wrapped, *args)
TypeError: 'AnonymousUser' object is not iterable
[2020-10-27 14:34:24,413] [basehttp.py:124] [basehttp:log_message] [ERROR]- "GET /novels/show_bookrack HTTP/1.1" 500 112847
[2020-10-27 14:34:25,850] [exception.py:118] [exception:handle_uncaught_exception] [ERROR]- Internal Server Error: /novels/show_bookrack
Traceback (most recent call last):
  File "D:\Envs\Django2020\lib\site-packages\django\core\handlers\exception.py", line 35, in inner
    response = get_response(request)
  File "D:\Envs\Django2020\lib\site-packages\django\core\handlers\base.py", line 128, in _get_response
    response = self.process_exception_by_middleware(e, request)
  File "D:\Envs\Django2020\lib\site-packages\django\core\handlers\base.py", line 126, in _get_response
    response = wrapped_callback(request, *callback_args, **callback_kwargs)
  File "C:\Users\xinxi\PycharmProjects\Qinxiangshuge\novels\views.py", line 101, in show_bookrack
    mybookrack = MyBookrack.objects.filter(user=request.user)
  File "D:\Envs\Django2020\lib\site-packages\django\db\models\manager.py", line 82, in manager_method
    return getattr(self.get_queryset(), name)(*args, **kwargs)
  File "D:\Envs\Django2020\lib\site-packages\django\db\models\query.py", line 836, in filter
    return self._filter_or_exclude(False, *args, **kwargs)
  File "D:\Envs\Django2020\lib\site-packages\django\db\models\query.py", line 854, in _filter_or_exclude
    clone.query.add_q(Q(*args, **kwargs))
  File "D:\Envs\Django2020\lib\site-packages\django\db\models\sql\query.py", line 1252, in add_q
    clause, _ = self._add_q(q_object, self.used_aliases)
  File "D:\Envs\Django2020\lib\site-packages\django\db\models\sql\query.py", line 1276, in _add_q
    split_subq=split_subq,
  File "D:\Envs\Django2020\lib\site-packages\django\db\models\sql\query.py", line 1186, in build_filter
    self.check_related_objects(join_info.final_field, value, join_info.opts)
  File "D:\Envs\Django2020\lib\site-packages\django\db\models\sql\query.py", line 1052, in check_related_objects
    for v in value:
  File "D:\Envs\Django2020\lib\site-packages\django\utils\functional.py", line 216, in inner
    return func(self._wrapped, *args)
TypeError: 'AnonymousUser' object is not iterable
[2020-10-27 14:34:25,910] [basehttp.py:124] [basehttp:log_message] [ERROR]- "GET /novels/show_bookrack HTTP/1.1" 500 112847
[2020-10-27 14:34:26,825] [exception.py:118] [exception:handle_uncaught_exception] [ERROR]- Internal Server Error: /novels/show_bookrack
Traceback (most recent call last):
  File "D:\Envs\Django2020\lib\site-packages\django\core\handlers\exception.py", line 35, in inner
    response = get_response(request)
  File "D:\Envs\Django2020\lib\site-packages\django\core\handlers\base.py", line 128, in _get_response
    response = self.process_exception_by_middleware(e, request)
  File "D:\Envs\Django2020\lib\site-packages\django\core\handlers\base.py", line 126, in _get_response
    response = wrapped_callback(request, *callback_args, **callback_kwargs)
  File "C:\Users\xinxi\PycharmProjects\Qinxiangshuge\novels\views.py", line 101, in show_bookrack
    mybookrack = MyBookrack.objects.filter(user=request.user)
  File "D:\Envs\Django2020\lib\site-packages\django\db\models\manager.py", line 82, in manager_method
    return getattr(self.get_queryset(), name)(*args, **kwargs)
  File "D:\Envs\Django2020\lib\site-packages\django\db\models\query.py", line 836, in filter
    return self._filter_or_exclude(False, *args, **kwargs)
  File "D:\Envs\Django2020\lib\site-packages\django\db\models\query.py", line 854, in _filter_or_exclude
    clone.query.add_q(Q(*args, **kwargs))
  File "D:\Envs\Django2020\lib\site-packages\django\db\models\sql\query.py", line 1252, in add_q
    clause, _ = self._add_q(q_object, self.used_aliases)
  File "D:\Envs\Django2020\lib\site-packages\django\db\models\sql\query.py", line 1276, in _add_q
    split_subq=split_subq,
  File "D:\Envs\Django2020\lib\site-packages\django\db\models\sql\query.py", line 1186, in build_filter
    self.check_related_objects(join_info.final_field, value, join_info.opts)
  File "D:\Envs\Django2020\lib\site-packages\django\db\models\sql\query.py", line 1052, in check_related_objects
    for v in value:
  File "D:\Envs\Django2020\lib\site-packages\django\utils\functional.py", line 216, in inner
    return func(self._wrapped, *args)
TypeError: 'AnonymousUser' object is not iterable
[2020-10-27 14:34:26,892] [basehttp.py:124] [basehttp:log_message] [ERROR]- "GET /novels/show_bookrack HTTP/1.1" 500 112847
[2020-10-27 14:34:27,666] [exception.py:118] [exception:handle_uncaught_exception] [ERROR]- Internal Server Error: /novels/show_bookrack
Traceback (most recent call last):
  File "D:\Envs\Django2020\lib\site-packages\django\core\handlers\exception.py", line 35, in inner
    response = get_response(request)
  File "D:\Envs\Django2020\lib\site-packages\django\core\handlers\base.py", line 128, in _get_response
    response = self.process_exception_by_middleware(e, request)
  File "D:\Envs\Django2020\lib\site-packages\django\core\handlers\base.py", line 126, in _get_response
    response = wrapped_callback(request, *callback_args, **callback_kwargs)
  File "C:\Users\xinxi\PycharmProjects\Qinxiangshuge\novels\views.py", line 101, in show_bookrack
    mybookrack = MyBookrack.objects.filter(user=request.user)
  File "D:\Envs\Django2020\lib\site-packages\django\db\models\manager.py", line 82, in manager_method
    return getattr(self.get_queryset(), name)(*args, **kwargs)
  File "D:\Envs\Django2020\lib\site-packages\django\db\models\query.py", line 836, in filter
    return self._filter_or_exclude(False, *args, **kwargs)
  File "D:\Envs\Django2020\lib\site-packages\django\db\models\query.py", line 854, in _filter_or_exclude
    clone.query.add_q(Q(*args, **kwargs))
  File "D:\Envs\Django2020\lib\site-packages\django\db\models\sql\query.py", line 1252, in add_q
    clause, _ = self._add_q(q_object, self.used_aliases)
  File "D:\Envs\Django2020\lib\site-packages\django\db\models\sql\query.py", line 1276, in _add_q
    split_subq=split_subq,
  File "D:\Envs\Django2020\lib\site-packages\django\db\models\sql\query.py", line 1186, in build_filter
    self.check_related_objects(join_info.final_field, value, join_info.opts)
  File "D:\Envs\Django2020\lib\site-packages\django\db\models\sql\query.py", line 1052, in check_related_objects
    for v in value:
  File "D:\Envs\Django2020\lib\site-packages\django\utils\functional.py", line 216, in inner
    return func(self._wrapped, *args)
TypeError: 'AnonymousUser' object is not iterable
[2020-10-27 14:34:27,725] [basehttp.py:124] [basehttp:log_message] [ERROR]- "GET /novels/show_bookrack HTTP/1.1" 500 112847
[2020-10-27 14:34:28,196] [exception.py:118] [exception:handle_uncaught_exception] [ERROR]- Internal Server Error: /novels/show_bookrack
Traceback (most recent call last):
  File "D:\Envs\Django2020\lib\site-packages\django\core\handlers\exception.py", line 35, in inner
    response = get_response(request)
  File "D:\Envs\Django2020\lib\site-packages\django\core\handlers\base.py", line 128, in _get_response
    response = self.process_exception_by_middleware(e, request)
  File "D:\Envs\Django2020\lib\site-packages\django\core\handlers\base.py", line 126, in _get_response
    response = wrapped_callback(request, *callback_args, **callback_kwargs)
  File "C:\Users\xinxi\PycharmProjects\Qinxiangshuge\novels\views.py", line 101, in show_bookrack
    mybookrack = MyBookrack.objects.filter(user=request.user)
  File "D:\Envs\Django2020\lib\site-packages\django\db\models\manager.py", line 82, in manager_method
    return getattr(self.get_queryset(), name)(*args, **kwargs)
  File "D:\Envs\Django2020\lib\site-packages\django\db\models\query.py", line 836, in filter
    return self._filter_or_exclude(False, *args, **kwargs)
  File "D:\Envs\Django2020\lib\site-packages\django\db\models\query.py", line 854, in _filter_or_exclude
    clone.query.add_q(Q(*args, **kwargs))
  File "D:\Envs\Django2020\lib\site-packages\django\db\models\sql\query.py", line 1252, in add_q
    clause, _ = self._add_q(q_object, self.used_aliases)
  File "D:\Envs\Django2020\lib\site-packages\django\db\models\sql\query.py", line 1276, in _add_q
    split_subq=split_subq,
  File "D:\Envs\Django2020\lib\site-packages\django\db\models\sql\query.py", line 1186, in build_filter
    self.check_related_objects(join_info.final_field, value, join_info.opts)
  File "D:\Envs\Django2020\lib\site-packages\django\db\models\sql\query.py", line 1052, in check_related_objects
    for v in value:
  File "D:\Envs\Django2020\lib\site-packages\django\utils\functional.py", line 216, in inner
    return func(self._wrapped, *args)
TypeError: 'AnonymousUser' object is not iterable
[2020-10-27 14:34:28,259] [basehttp.py:124] [basehttp:log_message] [ERROR]- "GET /novels/show_bookrack HTTP/1.1" 500 112847
[2020-10-27 14:36:41,011] [exception.py:118] [exception:handle_uncaught_exception] [ERROR]- Internal Server Error: /novels/show_bookrack
Traceback (most recent call last):
  File "D:\Envs\Django2020\lib\site-packages\django\core\handlers\exception.py", line 35, in inner
    response = get_response(request)
  File "D:\Envs\Django2020\lib\site-packages\django\core\handlers\base.py", line 128, in _get_response
    response = self.process_exception_by_middleware(e, request)
  File "D:\Envs\Django2020\lib\site-packages\django\core\handlers\base.py", line 126, in _get_response
    response = wrapped_callback(request, *callback_args, **callback_kwargs)
  File "C:\Users\xinxi\PycharmProjects\Qinxiangshuge\novels\views.py", line 103, in show_bookrack
    if request.user.is_authenticated():
TypeError: 'bool' object is not callable
[2020-10-27 14:36:41,173] [basehttp.py:124] [basehttp:log_message] [ERROR]- "GET /novels/show_bookrack HTTP/1.1" 500 74279
[2020-10-27 14:37:44,392] [exception.py:118] [exception:handle_uncaught_exception] [ERROR]- Internal Server Error: /novels/show_bookrack
Traceback (most recent call last):
  File "D:\Envs\Django2020\lib\site-packages\django\core\handlers\exception.py", line 35, in inner
    response = get_response(request)
  File "D:\Envs\Django2020\lib\site-packages\django\core\handlers\base.py", line 128, in _get_response
    response = self.process_exception_by_middleware(e, request)
  File "D:\Envs\Django2020\lib\site-packages\django\core\handlers\base.py", line 126, in _get_response
    response = wrapped_callback(request, *callback_args, **callback_kwargs)
  File "C:\Users\xinxi\PycharmProjects\Qinxiangshuge\novels\views.py", line 103, in show_bookrack
    if request.user.is_authenticated():
TypeError: 'bool' object is not callable
[2020-10-27 14:37:44,509] [basehttp.py:124] [basehttp:log_message] [ERROR]- "GET /novels/show_bookrack HTTP/1.1" 500 74324
[2020-10-27 14:37:47,740] [exception.py:118] [exception:handle_uncaught_exception] [ERROR]- Internal Server Error: /novels/show_bookrack
Traceback (most recent call last):
  File "D:\Envs\Django2020\lib\site-packages\django\core\handlers\exception.py", line 35, in inner
    response = get_response(request)
  File "D:\Envs\Django2020\lib\site-packages\django\core\handlers\base.py", line 128, in _get_response
    response = self.process_exception_by_middleware(e, request)
  File "D:\Envs\Django2020\lib\site-packages\django\core\handlers\base.py", line 126, in _get_response
    response = wrapped_callback(request, *callback_args, **callback_kwargs)
  File "C:\Users\xinxi\PycharmProjects\Qinxiangshuge\novels\views.py", line 103, in show_bookrack
    if request.user.is_authenticated():
TypeError: 'bool' object is not callable
[2020-10-27 14:37:47,782] [basehttp.py:124] [basehttp:log_message] [ERROR]- "GET /novels/show_bookrack HTTP/1.1" 500 74323
[2020-10-27 14:41:40,199] [exception.py:118] [exception:handle_uncaught_exception] [ERROR]- Internal Server Error: /novels/show_bookrack
Traceback (most recent call last):
  File "D:\Envs\Django2020\lib\site-packages\django\core\handlers\exception.py", line 35, in inner
    response = get_response(request)
  File "D:\Envs\Django2020\lib\site-packages\django\core\handlers\base.py", line 128, in _get_response
    response = self.process_exception_by_middleware(e, request)
  File "D:\Envs\Django2020\lib\site-packages\django\core\handlers\base.py", line 126, in _get_response
    response = wrapped_callback(request, *callback_args, **callback_kwargs)
  File "C:\Users\xinxi\PycharmProjects\Qinxiangshuge\novels\views.py", line 101, in show_bookrack
    mybookrack = MyBookrack.objects.filter(user=request.user)
  File "D:\Envs\Django2020\lib\site-packages\django\db\models\manager.py", line 82, in manager_method
    return getattr(self.get_queryset(), name)(*args, **kwargs)
  File "D:\Envs\Django2020\lib\site-packages\django\db\models\query.py", line 836, in filter
    return self._filter_or_exclude(False, *args, **kwargs)
  File "D:\Envs\Django2020\lib\site-packages\django\db\models\query.py", line 854, in _filter_or_exclude
    clone.query.add_q(Q(*args, **kwargs))
  File "D:\Envs\Django2020\lib\site-packages\django\db\models\sql\query.py", line 1252, in add_q
    clause, _ = self._add_q(q_object, self.used_aliases)
  File "D:\Envs\Django2020\lib\site-packages\django\db\models\sql\query.py", line 1276, in _add_q
    split_subq=split_subq,
  File "D:\Envs\Django2020\lib\site-packages\django\db\models\sql\query.py", line 1186, in build_filter
    self.check_related_objects(join_info.final_field, value, join_info.opts)
  File "D:\Envs\Django2020\lib\site-packages\django\db\models\sql\query.py", line 1052, in check_related_objects
    for v in value:
  File "D:\Envs\Django2020\lib\site-packages\django\utils\functional.py", line 216, in inner
    return func(self._wrapped, *args)
TypeError: 'AnonymousUser' object is not iterable
[2020-10-27 14:41:40,377] [basehttp.py:124] [basehttp:log_message] [ERROR]- "GET /novels/show_bookrack HTTP/1.1" 500 112847
[2020-10-27 14:42:43,783] [exception.py:118] [exception:handle_uncaught_exception] [ERROR]- Internal Server Error: /novels/show_bookrack
Traceback (most recent call last):
  File "D:\Envs\Django2020\lib\site-packages\django\core\handlers\exception.py", line 35, in inner
    response = get_response(request)
  File "D:\Envs\Django2020\lib\site-packages\django\core\handlers\base.py", line 128, in _get_response
    response = self.process_exception_by_middleware(e, request)
  File "D:\Envs\Django2020\lib\site-packages\django\core\handlers\base.py", line 126, in _get_response
    response = wrapped_callback(request, *callback_args, **callback_kwargs)
  File "C:\Users\xinxi\PycharmProjects\Qinxiangshuge\novels\views.py", line 101, in show_bookrack
    mybookrack = MyBookrack.objects.filter(user=request.user)
  File "D:\Envs\Django2020\lib\site-packages\django\db\models\manager.py", line 82, in manager_method
    return getattr(self.get_queryset(), name)(*args, **kwargs)
  File "D:\Envs\Django2020\lib\site-packages\django\db\models\query.py", line 836, in filter
    return self._filter_or_exclude(False, *args, **kwargs)
  File "D:\Envs\Django2020\lib\site-packages\django\db\models\query.py", line 854, in _filter_or_exclude
    clone.query.add_q(Q(*args, **kwargs))
  File "D:\Envs\Django2020\lib\site-packages\django\db\models\sql\query.py", line 1252, in add_q
    clause, _ = self._add_q(q_object, self.used_aliases)
  File "D:\Envs\Django2020\lib\site-packages\django\db\models\sql\query.py", line 1276, in _add_q
    split_subq=split_subq,
  File "D:\Envs\Django2020\lib\site-packages\django\db\models\sql\query.py", line 1186, in build_filter
    self.check_related_objects(join_info.final_field, value, join_info.opts)
  File "D:\Envs\Django2020\lib\site-packages\django\db\models\sql\query.py", line 1052, in check_related_objects
    for v in value:
  File "D:\Envs\Django2020\lib\site-packages\django\utils\functional.py", line 216, in inner
    return func(self._wrapped, *args)
TypeError: 'AnonymousUser' object is not iterable
[2020-10-27 14:42:43,870] [basehttp.py:124] [basehttp:log_message] [ERROR]- "GET /novels/show_bookrack HTTP/1.1" 500 112712
[2020-10-27 14:52:33,352] [exception.py:118] [exception:handle_uncaught_exception] [ERROR]- Internal Server Error: /novels/show_bookrack
Traceback (most recent call last):
  File "D:\Envs\Django2020\lib\site-packages\django\core\handlers\exception.py", line 35, in inner
    response = get_response(request)
  File "D:\Envs\Django2020\lib\site-packages\django\core\handlers\base.py", line 119, in _get_response
    response = middleware_method(request, callback, callback_args, callback_kwargs)
  File "C:\Users\xinxi\PycharmProjects\Qinxiangshuge\middleware\login_middleware.py", line 21, in process_view
    callback(request) #视图函数对象，传人request，相当于调用了视图函数
  File "C:\Users\xinxi\PycharmProjects\Qinxiangshuge\novels\views.py", line 101, in show_bookrack
    mybookrack = MyBookrack.objects.filter(user=request.user)
  File "D:\Envs\Django2020\lib\site-packages\django\db\models\manager.py", line 82, in manager_method
    return getattr(self.get_queryset(), name)(*args, **kwargs)
  File "D:\Envs\Django2020\lib\site-packages\django\db\models\query.py", line 836, in filter
    return self._filter_or_exclude(False, *args, **kwargs)
  File "D:\Envs\Django2020\lib\site-packages\django\db\models\query.py", line 854, in _filter_or_exclude
    clone.query.add_q(Q(*args, **kwargs))
  File "D:\Envs\Django2020\lib\site-packages\django\db\models\sql\query.py", line 1252, in add_q
    clause, _ = self._add_q(q_object, self.used_aliases)
  File "D:\Envs\Django2020\lib\site-packages\django\db\models\sql\query.py", line 1276, in _add_q
    split_subq=split_subq,
  File "D:\Envs\Django2020\lib\site-packages\django\db\models\sql\query.py", line 1186, in build_filter
    self.check_related_objects(join_info.final_field, value, join_info.opts)
  File "D:\Envs\Django2020\lib\site-packages\django\db\models\sql\query.py", line 1052, in check_related_objects
    for v in value:
  File "D:\Envs\Django2020\lib\site-packages\django\utils\functional.py", line 216, in inner
    return func(self._wrapped, *args)
TypeError: 'AnonymousUser' object is not iterable
[2020-10-27 14:52:33,492] [basehttp.py:124] [basehttp:log_message] [ERROR]- "GET /novels/show_bookrack HTTP/1.1" 500 111055
[2020-10-27 14:52:35,107] [exception.py:118] [exception:handle_uncaught_exception] [ERROR]- Internal Server Error: /novels/show_bookrack
Traceback (most recent call last):
  File "D:\Envs\Django2020\lib\site-packages\django\core\handlers\exception.py", line 35, in inner
    response = get_response(request)
  File "D:\Envs\Django2020\lib\site-packages\django\core\handlers\base.py", line 119, in _get_response
    response = middleware_method(request, callback, callback_args, callback_kwargs)
  File "C:\Users\xinxi\PycharmProjects\Qinxiangshuge\middleware\login_middleware.py", line 21, in process_view
    callback(request) #视图函数对象，传人request，相当于调用了视图函数
  File "C:\Users\xinxi\PycharmProjects\Qinxiangshuge\novels\views.py", line 101, in show_bookrack
    mybookrack = MyBookrack.objects.filter(user=request.user)
  File "D:\Envs\Django2020\lib\site-packages\django\db\models\manager.py", line 82, in manager_method
    return getattr(self.get_queryset(), name)(*args, **kwargs)
  File "D:\Envs\Django2020\lib\site-packages\django\db\models\query.py", line 836, in filter
    return self._filter_or_exclude(False, *args, **kwargs)
  File "D:\Envs\Django2020\lib\site-packages\django\db\models\query.py", line 854, in _filter_or_exclude
    clone.query.add_q(Q(*args, **kwargs))
  File "D:\Envs\Django2020\lib\site-packages\django\db\models\sql\query.py", line 1252, in add_q
    clause, _ = self._add_q(q_object, self.used_aliases)
  File "D:\Envs\Django2020\lib\site-packages\django\db\models\sql\query.py", line 1276, in _add_q
    split_subq=split_subq,
  File "D:\Envs\Django2020\lib\site-packages\django\db\models\sql\query.py", line 1186, in build_filter
    self.check_related_objects(join_info.final_field, value, join_info.opts)
  File "D:\Envs\Django2020\lib\site-packages\django\db\models\sql\query.py", line 1052, in check_related_objects
    for v in value:
  File "D:\Envs\Django2020\lib\site-packages\django\utils\functional.py", line 216, in inner
    return func(self._wrapped, *args)
TypeError: 'AnonymousUser' object is not iterable
[2020-10-27 14:52:35,167] [basehttp.py:124] [basehttp:log_message] [ERROR]- "GET /novels/show_bookrack HTTP/1.1" 500 111190
[2020-10-27 14:54:02,949] [exception.py:118] [exception:handle_uncaught_exception] [ERROR]- Internal Server Error: /novels/detail/1111
Traceback (most recent call last):
  File "D:\Envs\Django2020\lib\site-packages\django\core\handlers\exception.py", line 35, in inner
    response = get_response(request)
  File "D:\Envs\Django2020\lib\site-packages\django\core\handlers\base.py", line 119, in _get_response
    response = middleware_method(request, callback, callback_args, callback_kwargs)
  File "C:\Users\xinxi\PycharmProjects\Qinxiangshuge\middleware\login_middleware.py", line 21, in process_view
    callback(request) #视图函数对象，传人request，相当于调用了视图函数
TypeError: novel_detail() missing 1 required positional argument: 'gid'
[2020-10-27 14:54:03,077] [basehttp.py:124] [basehttp:log_message] [ERROR]- "GET /novels/detail/1111 HTTP/1.1" 500 69404
[2020-10-27 14:54:11,791] [views.py:25] [views:index] [INFO]- 缓存中的key为：None----浏览器中的key为:2f712a18181c11ebaabc5800e3fb0696
[2020-10-27 14:54:11,814] [exception.py:118] [exception:handle_uncaught_exception] [ERROR]- Internal Server Error: /novels/index
Traceback (most recent call last):
  File "D:\Envs\Django2020\lib\site-packages\django\core\handlers\base.py", line 126, in _get_response
    response = wrapped_callback(request, *callback_args, **callback_kwargs)
  File "C:\Users\xinxi\PycharmProjects\Qinxiangshuge\novels\views.py", line 24, in index
    liulanqi_key = cache.get('liulanqi:' + user.uid)
AttributeError: 'NoneType' object has no attribute 'uid'

During handling of the above exception, another exception occurred:

Traceback (most recent call last):
  File "D:\Envs\Django2020\lib\site-packages\django\core\handlers\exception.py", line 35, in inner
    response = get_response(request)
  File "D:\Envs\Django2020\lib\site-packages\django\core\handlers\base.py", line 128, in _get_response
    response = self.process_exception_by_middleware(e, request)
  File "D:\Envs\Django2020\lib\site-packages\django\core\handlers\base.py", line 168, in process_exception_by_middleware
    response = middleware_method(request, exception)
  File "C:\Users\xinxi\PycharmProjects\Qinxiangshuge\middleware\login_middleware.py", line 18, in process_exception
    return render(request,'500error.html')
  File "D:\Envs\Django2020\lib\site-packages\django\shortcuts.py", line 36, in render
    content = loader.render_to_string(template_name, context, request, using=using)
  File "D:\Envs\Django2020\lib\site-packages\django\template\loader.py", line 61, in render_to_string
    template = get_template(template_name, using=using)
  File "D:\Envs\Django2020\lib\site-packages\django\template\loader.py", line 19, in get_template
    raise TemplateDoesNotExist(template_name, chain=chain)
django.template.exceptions.TemplateDoesNotExist: 500error.html
[2020-10-27 14:54:11,870] [basehttp.py:124] [basehttp:log_message] [ERROR]- "GET /novels/index HTTP/1.1" 500 98265
[2020-10-27 14:54:17,545] [basehttp.py:124] [basehttp:log_message] [INFO]- "GET /user/login HTTP/1.1" 200 4227
[2020-10-27 14:54:17,649] [basehttp.py:124] [basehttp:log_message] [INFO]- "GET /user/draw HTTP/1.1" 200 2466
[2020-10-27 14:54:27,423] [basehttp.py:124] [basehttp:log_message] [INFO]- "POST /user/login HTTP/1.1" 302 0
[2020-10-27 14:54:27,438] [views.py:25] [views:index] [INFO]- 缓存中的key为：3b750bcc182111eb860d5800e3fb0696----浏览器中的key为:3b750bcc182111eb860d5800e3fb0696
[2020-10-27 14:54:27,507] [views.py:25] [views:index] [INFO]- 缓存中的key为：3b750bcc182111eb860d5800e3fb0696----浏览器中的key为:3b750bcc182111eb860d5800e3fb0696
[2020-10-27 14:54:27,578] [basehttp.py:124] [basehttp:log_message] [INFO]- "GET /novels/index HTTP/1.1" 200 17943
[2020-10-27 14:54:27,686] [basehttp.py:124] [basehttp:log_message] [INFO]- "GET /static/media/type/58950l.jpg HTTP/1.1" 200 335654
[2020-10-27 14:54:27,698] [basehttp.py:124] [basehttp:log_message] [INFO]- "GET /static/media/type/58950l_5kfSspN.jpg HTTP/1.1" 200 335654
[2020-10-27 14:54:27,731] [basehttp.py:124] [basehttp:log_message] [INFO]- "GET /static/media/type/58950l_O9lXQZR.jpg HTTP/1.1" 200 335654
[2020-10-27 14:54:27,732] [basehttp.py:124] [basehttp:log_message] [INFO]- "GET /static/media/type/57304l.jpg HTTP/1.1" 200 138618
[2020-10-27 14:54:27,741] [basehttp.py:124] [basehttp:log_message] [INFO]- "GET /static/media/banner/8797s.jpg HTTP/1.1" 200 15649
[2020-10-27 14:54:27,745] [basehttp.py:124] [basehttp:log_message] [INFO]- "GET /static/media/type/57840l.jpg HTTP/1.1" 200 161173
[2020-10-27 14:54:27,746] [basehttp.py:124] [basehttp:log_message] [INFO]- "GET /static/media/banner/57304l.jpg HTTP/1.1" 200 138618
[2020-10-27 14:54:27,749] [basehttp.py:124] [basehttp:log_message] [INFO]- "GET /static/media/type/59178l.jpg HTTP/1.1" 200 356232
[2020-10-27 14:54:34,570] [exception.py:118] [exception:handle_uncaught_exception] [ERROR]- Internal Server Error: /novels/detail/11111111
Traceback (most recent call last):
  File "D:\Envs\Django2020\lib\site-packages\django\core\handlers\exception.py", line 35, in inner
    response = get_response(request)
  File "D:\Envs\Django2020\lib\site-packages\django\core\handlers\base.py", line 119, in _get_response
    response = middleware_method(request, callback, callback_args, callback_kwargs)
  File "C:\Users\xinxi\PycharmProjects\Qinxiangshuge\middleware\login_middleware.py", line 21, in process_view
    callback(request) #视图函数对象，传人request，相当于调用了视图函数
TypeError: novel_detail() missing 1 required positional argument: 'gid'
[2020-10-27 14:54:34,622] [basehttp.py:124] [basehttp:log_message] [ERROR]- "GET /novels/detail/11111111 HTTP/1.1" 500 69196
[2020-10-27 14:54:58,748] [exception.py:118] [exception:handle_uncaught_exception] [ERROR]- Internal Server Error: /novels/detail/1111
Traceback (most recent call last):
  File "D:\Envs\Django2020\lib\site-packages\django\core\handlers\exception.py", line 35, in inner
    response = get_response(request)
  File "D:\Envs\Django2020\lib\site-packages\django\core\handlers\base.py", line 119, in _get_response
    response = middleware_method(request, callback, callback_args, callback_kwargs)
  File "C:\Users\xinxi\PycharmProjects\Qinxiangshuge\middleware\login_middleware.py", line 21, in process_view
    callback(request) #视图函数对象，传人request，相当于调用了视图函数
TypeError: novel_detail() missing 1 required positional argument: 'gid'
[2020-10-27 14:54:58,791] [basehttp.py:124] [basehttp:log_message] [ERROR]- "GET /novels/detail/1111 HTTP/1.1" 500 69144
[2020-10-27 14:56:31,473] [basehttp.py:124] [basehttp:log_message] [INFO]- "GET /novels/detail/1111 HTTP/1.1" 200 8314
[2020-10-27 14:56:42,514] [basehttp.py:124] [basehttp:log_message] [INFO]- "GET /novels/novelbody/44444444 HTTP/1.1" 200 13026
[2020-10-27 14:56:51,964] [exception.py:118] [exception:handle_uncaught_exception] [ERROR]- Internal Server Error: /novels/show_bookrack
Traceback (most recent call last):
  File "D:\Envs\Django2020\lib\site-packages\django\core\handlers\exception.py", line 35, in inner
    response = get_response(request)
  File "D:\Envs\Django2020\lib\site-packages\django\core\handlers\base.py", line 128, in _get_response
    response = self.process_exception_by_middleware(e, request)
  File "D:\Envs\Django2020\lib\site-packages\django\core\handlers\base.py", line 126, in _get_response
    response = wrapped_callback(request, *callback_args, **callback_kwargs)
  File "C:\Users\xinxi\PycharmProjects\Qinxiangshuge\novels\views.py", line 101, in show_bookrack
    mybookrack = MyBookrack.objects.filter(user=request.user)
  File "D:\Envs\Django2020\lib\site-packages\django\db\models\manager.py", line 82, in manager_method
    return getattr(self.get_queryset(), name)(*args, **kwargs)
  File "D:\Envs\Django2020\lib\site-packages\django\db\models\query.py", line 836, in filter
    return self._filter_or_exclude(False, *args, **kwargs)
  File "D:\Envs\Django2020\lib\site-packages\django\db\models\query.py", line 854, in _filter_or_exclude
    clone.query.add_q(Q(*args, **kwargs))
  File "D:\Envs\Django2020\lib\site-packages\django\db\models\sql\query.py", line 1252, in add_q
    clause, _ = self._add_q(q_object, self.used_aliases)
  File "D:\Envs\Django2020\lib\site-packages\django\db\models\sql\query.py", line 1276, in _add_q
    split_subq=split_subq,
  File "D:\Envs\Django2020\lib\site-packages\django\db\models\sql\query.py", line 1186, in build_filter
    self.check_related_objects(join_info.final_field, value, join_info.opts)
  File "D:\Envs\Django2020\lib\site-packages\django\db\models\sql\query.py", line 1052, in check_related_objects
    for v in value:
  File "D:\Envs\Django2020\lib\site-packages\django\utils\functional.py", line 216, in inner
    return func(self._wrapped, *args)
TypeError: 'AnonymousUser' object is not iterable
[2020-10-27 14:56:52,041] [basehttp.py:124] [basehttp:log_message] [ERROR]- "GET /novels/show_bookrack HTTP/1.1" 500 112959
[2020-10-27 14:59:51,473] [exception.py:118] [exception:handle_uncaught_exception] [ERROR]- Internal Server Error: /novels/show_bookrack
Traceback (most recent call last):
  File "D:\Envs\Django2020\lib\site-packages\django\core\handlers\exception.py", line 35, in inner
    response = get_response(request)
  File "D:\Envs\Django2020\lib\site-packages\django\core\handlers\base.py", line 128, in _get_response
    response = self.process_exception_by_middleware(e, request)
  File "D:\Envs\Django2020\lib\site-packages\django\core\handlers\base.py", line 126, in _get_response
    response = wrapped_callback(request, *callback_args, **callback_kwargs)
  File "C:\Users\xinxi\PycharmProjects\Qinxiangshuge\novels\views.py", line 102, in show_bookrack
    if request.user.is_authenticated():
TypeError: 'bool' object is not callable
[2020-10-27 14:59:51,592] [basehttp.py:124] [basehttp:log_message] [ERROR]- "GET /novels/show_bookrack HTTP/1.1" 500 74558
[2020-10-27 14:59:52,783] [exception.py:118] [exception:handle_uncaught_exception] [ERROR]- Internal Server Error: /novels/show_bookrack
Traceback (most recent call last):
  File "D:\Envs\Django2020\lib\site-packages\django\core\handlers\exception.py", line 35, in inner
    response = get_response(request)
  File "D:\Envs\Django2020\lib\site-packages\django\core\handlers\base.py", line 128, in _get_response
    response = self.process_exception_by_middleware(e, request)
  File "D:\Envs\Django2020\lib\site-packages\django\core\handlers\base.py", line 126, in _get_response
    response = wrapped_callback(request, *callback_args, **callback_kwargs)
  File "C:\Users\xinxi\PycharmProjects\Qinxiangshuge\novels\views.py", line 102, in show_bookrack
    if request.user.is_authenticated():
TypeError: 'bool' object is not callable
[2020-10-27 14:59:52,821] [basehttp.py:124] [basehttp:log_message] [ERROR]- "GET /novels/show_bookrack HTTP/1.1" 500 74559
[2020-10-27 14:59:53,844] [exception.py:118] [exception:handle_uncaught_exception] [ERROR]- Internal Server Error: /novels/show_bookrack
Traceback (most recent call last):
  File "D:\Envs\Django2020\lib\site-packages\django\core\handlers\exception.py", line 35, in inner
    response = get_response(request)
  File "D:\Envs\Django2020\lib\site-packages\django\core\handlers\base.py", line 128, in _get_response
    response = self.process_exception_by_middleware(e, request)
  File "D:\Envs\Django2020\lib\site-packages\django\core\handlers\base.py", line 126, in _get_response
    response = wrapped_callback(request, *callback_args, **callback_kwargs)
  File "C:\Users\xinxi\PycharmProjects\Qinxiangshuge\novels\views.py", line 102, in show_bookrack
    if request.user.is_authenticated():
TypeError: 'bool' object is not callable
[2020-10-27 14:59:53,882] [basehttp.py:124] [basehttp:log_message] [ERROR]- "GET /novels/show_bookrack HTTP/1.1" 500 74559
[2020-10-27 15:04:19,732] [exception.py:118] [exception:handle_uncaught_exception] [ERROR]- Internal Server Error: /novels/show_bookrack
Traceback (most recent call last):
  File "D:\Envs\Django2020\lib\site-packages\django\core\handlers\exception.py", line 35, in inner
    response = get_response(request)
  File "D:\Envs\Django2020\lib\site-packages\django\core\handlers\base.py", line 128, in _get_response
    response = self.process_exception_by_middleware(e, request)
  File "D:\Envs\Django2020\lib\site-packages\django\core\handlers\base.py", line 126, in _get_response
    response = wrapped_callback(request, *callback_args, **callback_kwargs)
  File "C:\Users\xinxi\PycharmProjects\Qinxiangshuge\novels\views.py", line 102, in show_bookrack
    if request.user.is_authenticated():
TypeError: 'bool' object is not callable
[2020-10-27 15:04:19,854] [basehttp.py:124] [basehttp:log_message] [ERROR]- "GET /novels/show_bookrack HTTP/1.1" 500 74559
[2020-10-27 15:04:22,175] [exception.py:118] [exception:handle_uncaught_exception] [ERROR]- Internal Server Error: /novels/show_bookrack
Traceback (most recent call last):
  File "D:\Envs\Django2020\lib\site-packages\django\core\handlers\exception.py", line 35, in inner
    response = get_response(request)
  File "D:\Envs\Django2020\lib\site-packages\django\core\handlers\base.py", line 128, in _get_response
    response = self.process_exception_by_middleware(e, request)
  File "D:\Envs\Django2020\lib\site-packages\django\core\handlers\base.py", line 126, in _get_response
    response = wrapped_callback(request, *callback_args, **callback_kwargs)
  File "C:\Users\xinxi\PycharmProjects\Qinxiangshuge\novels\views.py", line 102, in show_bookrack
    if request.user.is_authenticated():
TypeError: 'bool' object is not callable
[2020-10-27 15:04:22,216] [basehttp.py:124] [basehttp:log_message] [ERROR]- "GET /novels/show_bookrack HTTP/1.1" 500 74559
[2020-10-27 15:07:44,462] [exception.py:118] [exception:handle_uncaught_exception] [ERROR]- Internal Server Error: /novels/show_bookrack
Traceback (most recent call last):
  File "D:\Envs\Django2020\lib\site-packages\django\core\handlers\exception.py", line 35, in inner
    response = get_response(request)
  File "D:\Envs\Django2020\lib\site-packages\django\core\handlers\base.py", line 139, in _get_response
    "returned None instead." % (callback.__module__, view_name)
ValueError: The view novels.views.show_bookrack didn't return an HttpResponse object. It returned None instead.
[2020-10-27 15:07:44,583] [basehttp.py:124] [basehttp:log_message] [ERROR]- "GET /novels/show_bookrack HTTP/1.1" 500 65747
[2020-10-27 15:11:15,179] [exception.py:118] [exception:handle_uncaught_exception] [ERROR]- Internal Server Error: /novels/show_bookrack
Traceback (most recent call last):
  File "D:\Envs\Django2020\lib\site-packages\django\core\handlers\exception.py", line 35, in inner
    response = get_response(request)
  File "D:\Envs\Django2020\lib\site-packages\django\core\handlers\base.py", line 139, in _get_response
    "returned None instead." % (callback.__module__, view_name)
ValueError: The view novels.views.show_bookrack didn't return an HttpResponse object. It returned None instead.
[2020-10-27 15:11:15,300] [basehttp.py:124] [basehttp:log_message] [ERROR]- "GET /novels/show_bookrack HTTP/1.1" 500 65748
[2020-10-27 15:11:16,194] [exception.py:118] [exception:handle_uncaught_exception] [ERROR]- Internal Server Error: /novels/show_bookrack
Traceback (most recent call last):
  File "D:\Envs\Django2020\lib\site-packages\django\core\handlers\exception.py", line 35, in inner
    response = get_response(request)
  File "D:\Envs\Django2020\lib\site-packages\django\core\handlers\base.py", line 139, in _get_response
    "returned None instead." % (callback.__module__, view_name)
ValueError: The view novels.views.show_bookrack didn't return an HttpResponse object. It returned None instead.
[2020-10-27 15:11:16,230] [basehttp.py:124] [basehttp:log_message] [ERROR]- "GET /novels/show_bookrack HTTP/1.1" 500 65747
[2020-10-27 15:15:25,453] [basehttp.py:124] [basehttp:log_message] [INFO]- "GET /novels/show_bookrack HTTP/1.1" 200 6172
[2020-10-27 15:15:28,193] [basehttp.py:124] [basehttp:log_message] [INFO]- "GET /novels/show_bookrack HTTP/1.1" 200 6172
[2020-10-27 15:15:28,758] [basehttp.py:124] [basehttp:log_message] [INFO]- "GET /novels/show_bookrack HTTP/1.1" 200 6172
[2020-10-27 15:15:29,013] [basehttp.py:124] [basehttp:log_message] [INFO]- "GET /novels/show_bookrack HTTP/1.1" 200 6172
[2020-10-27 15:15:29,199] [basehttp.py:124] [basehttp:log_message] [INFO]- "GET /novels/show_bookrack HTTP/1.1" 200 6172
[2020-10-27 15:16:00,762] [basehttp.py:124] [basehttp:log_message] [INFO]- "GET /novels/show_bookrack HTTP/1.1" 200 6172
[2020-10-27 15:16:01,436] [basehttp.py:124] [basehttp:log_message] [INFO]- "GET /novels/show_bookrack HTTP/1.1" 200 6172
[2020-10-27 15:16:01,674] [basehttp.py:124] [basehttp:log_message] [INFO]- "GET /novels/show_bookrack HTTP/1.1" 200 6172
[2020-10-27 15:16:01,878] [basehttp.py:124] [basehttp:log_message] [INFO]- "GET /novels/show_bookrack HTTP/1.1" 200 6172
[2020-10-27 15:16:16,313] [basehttp.py:124] [basehttp:log_message] [INFO]- "GET /novels/show_bookrack HTTP/1.1" 200 6172
[2020-10-27 15:16:37,522] [basehttp.py:124] [basehttp:log_message] [INFO]- "GET /novels/show_bookrack HTTP/1.1" 200 6172
[2020-10-27 15:16:38,891] [basehttp.py:124] [basehttp:log_message] [INFO]- "GET /novels/show_bookrack HTTP/1.1" 200 6172
[2020-10-27 15:16:39,952] [basehttp.py:124] [basehttp:log_message] [INFO]- "GET /novels/show_bookrack HTTP/1.1" 200 6172
[2020-10-27 15:16:55,844] [basehttp.py:124] [basehttp:log_message] [INFO]- "GET /novels/show_bookrack HTTP/1.1" 200 6172
[2020-10-27 15:17:38,240] [basehttp.py:124] [basehttp:log_message] [INFO]- "GET /novels/novelbody/44444444 HTTP/1.1" 200 13026
[2020-10-27 15:17:43,322] [exception.py:118] [exception:handle_uncaught_exception] [ERROR]- Internal Server Error: /novels/show_bookrack
Traceback (most recent call last):
  File "D:\Envs\Django2020\lib\site-packages\django\core\handlers\exception.py", line 35, in inner
    response = get_response(request)
  File "D:\Envs\Django2020\lib\site-packages\django\core\handlers\base.py", line 139, in _get_response
    "returned None instead." % (callback.__module__, view_name)
ValueError: The view novels.views.show_bookrack didn't return an HttpResponse object. It returned None instead.
[2020-10-27 15:17:43,439] [basehttp.py:124] [basehttp:log_message] [ERROR]- "GET /novels/show_bookrack HTTP/1.1" 500 65613
[2020-10-27 15:17:57,861] [basehttp.py:124] [basehttp:log_message] [INFO]- "GET /novels/show_bookrack HTTP/1.1" 200 6172
[2020-10-27 15:18:41,826] [basehttp.py:124] [basehttp:log_message] [INFO]- "GET /novels/detail/1111 HTTP/1.1" 200 8314
[2020-10-27 15:18:44,011] [basehttp.py:124] [basehttp:log_message] [INFO]- "GET /user/logout HTTP/1.1" 302 0
[2020-10-27 15:18:44,022] [basehttp.py:124] [basehttp:log_message] [INFO]- "GET /user/login HTTP/1.1" 200 4227
[2020-10-27 15:18:44,062] [basehttp.py:124] [basehttp:log_message] [INFO]- "GET /user/draw HTTP/1.1" 200 2590
[2020-10-27 15:18:55,598] [basehttp.py:124] [basehttp:log_message] [INFO]- "POST /user/login HTTP/1.1" 302 0
[2020-10-27 15:18:55,612] [views.py:25] [views:index] [INFO]- 缓存中的key为：a58bb45c182411eb8a4a5800e3fb0696----浏览器中的key为:a58bb45c182411eb8a4a5800e3fb0696
[2020-10-27 15:18:55,680] [basehttp.py:124] [basehttp:log_message] [INFO]- "GET /novels/index HTTP/1.1" 200 17943
[2020-10-27 15:23:15,970] [views.py:25] [views:index] [INFO]- 缓存中的key为：a58bb45c182411eb8a4a5800e3fb0696----浏览器中的key为:a58bb45c182411eb8a4a5800e3fb0696
[2020-10-27 15:23:16,050] [basehttp.py:124] [basehttp:log_message] [INFO]- "GET /novels/index HTTP/1.1" 200 17963
[2020-10-27 15:23:17,117] [basehttp.py:124] [basehttp:log_message] [INFO]- "GET /novels/show_bookrack HTTP/1.1" 200 6192
[2020-10-27 15:24:11,934] [views.py:25] [views:index] [INFO]- 缓存中的key为：None----浏览器中的key为:a58bb45c182411eb8a4a5800e3fb0696
[2020-10-27 15:24:11,955] [basehttp.py:124] [basehttp:log_message] [INFO]- "GET /novels/index HTTP/1.1" 302 0
[2020-10-27 15:24:11,974] [basehttp.py:124] [basehttp:log_message] [INFO]- "GET /user/login HTTP/1.1" 200 4227
[2020-10-27 15:24:12,035] [basehttp.py:124] [basehttp:log_message] [INFO]- "GET /user/draw HTTP/1.1" 200 2800
[2020-10-27 15:24:19,837] [basehttp.py:124] [basehttp:log_message] [INFO]- "POST /user/login HTTP/1.1" 302 0
[2020-10-27 15:24:19,852] [views.py:25] [views:index] [INFO]- 缓存中的key为：69052fcc182511ebb1fd5800e3fb0696----浏览器中的key为:69052fcc182511ebb1fd5800e3fb0696
[2020-10-27 15:24:20,048] [basehttp.py:124] [basehttp:log_message] [INFO]- "GET /novels/index HTTP/1.1" 200 17963
[2020-10-27 15:24:22,014] [basehttp.py:124] [basehttp:log_message] [INFO]- "GET /novels/show_bookrack HTTP/1.1" 200 6192
[2020-10-27 15:24:23,859] [views.py:25] [views:index] [INFO]- 缓存中的key为：69052fcc182511ebb1fd5800e3fb0696----浏览器中的key为:69052fcc182511ebb1fd5800e3fb0696
[2020-10-27 15:24:23,940] [basehttp.py:124] [basehttp:log_message] [INFO]- "GET /novels/index HTTP/1.1" 200 17963
[2020-10-27 15:24:26,404] [basehttp.py:124] [basehttp:log_message] [INFO]- "GET /novels/detail/1111 HTTP/1.1" 200 8334
[2020-10-27 15:25:52,537] [basehttp.py:124] [basehttp:log_message] [INFO]- "GET /novels/detail/1111 HTTP/1.1" 200 8334
[2020-10-27 15:33:21,393] [basehttp.py:124] [basehttp:log_message] [INFO]- "GET /novels/detail/1111 HTTP/1.1" 200 8333
[2020-10-27 15:33:21,430] [basehttp.py:124] [basehttp:log_message] [INFO]- "GET /static/media/novels/58950l.jpg HTTP/1.1" 200 335654
[2020-10-27 15:33:27,010] [basehttp.py:124] [basehttp:log_message] [INFO]- "GET /novels/detail/1111 HTTP/1.1" 200 8333
[2020-10-27 15:33:27,045] [basehttp.py:124] [basehttp:log_message] [INFO]- "GET /static/media/novels/58950l.jpg HTTP/1.1" 200 335654
[2020-10-27 15:33:28,080] [basehttp.py:124] [basehttp:log_message] [INFO]- "GET /novels/detail/1111 HTTP/1.1" 200 8333
[2020-10-27 15:33:28,116] [basehttp.py:124] [basehttp:log_message] [INFO]- "GET /static/media/novels/58950l.jpg HTTP/1.1" 200 335654
[2020-10-27 15:33:53,710] [basehttp.py:124] [basehttp:log_message] [INFO]- "GET /novels/detail/1111 HTTP/1.1" 200 8335
[2020-10-27 15:33:53,758] [basehttp.py:124] [basehttp:log_message] [INFO]- "GET /static/media/novels/58950l.jpg HTTP/1.1" 200 335654
[2020-10-27 15:35:32,963] [basehttp.py:124] [basehttp:log_message] [INFO]- "GET /novels/detail/1111 HTTP/1.1" 200 8334
[2020-10-27 15:35:32,999] [basehttp.py:124] [basehttp:log_message] [INFO]- "GET /static/media/novels/58950l.jpg HTTP/1.1" 200 335654
[2020-10-27 15:37:03,753] [basehttp.py:124] [basehttp:log_message] [INFO]- "GET /novels/detail/1111 HTTP/1.1" 200 8331
[2020-10-27 15:37:03,782] [basehttp.py:124] [basehttp:log_message] [INFO]- "GET /static/media/novels/58950l.jpg HTTP/1.1" 200 335654
[2020-10-27 15:37:41,706] [basehttp.py:124] [basehttp:log_message] [INFO]- "GET /novels/detail/1111 HTTP/1.1" 200 8331
[2020-10-27 15:37:41,744] [basehttp.py:124] [basehttp:log_message] [INFO]- "GET /static/media/novels/58950l.jpg HTTP/1.1" 200 335654
[2020-10-27 15:38:13,823] [basehttp.py:124] [basehttp:log_message] [INFO]- "GET /novels/detail/1111 HTTP/1.1" 200 8273
[2020-10-27 15:38:13,854] [basehttp.py:124] [basehttp:log_message] [INFO]- "GET /static/media/novels/58950l.jpg HTTP/1.1" 200 335654
[2020-10-27 15:38:17,776] [exception.py:118] [exception:handle_uncaught_exception] [ERROR]- Internal Server Error: /novels/add_bookrack
Traceback (most recent call last):
  File "D:\Envs\Django2020\lib\site-packages\django\core\handlers\exception.py", line 35, in inner
    response = get_response(request)
  File "D:\Envs\Django2020\lib\site-packages\django\core\handlers\base.py", line 139, in _get_response
    "returned None instead." % (callback.__module__, view_name)
ValueError: The view novels.views.add_bookrack didn't return an HttpResponse object. It returned None instead.
[2020-10-27 15:38:17,811] [basehttp.py:124] [basehttp:log_message] [ERROR]- "GET /novels/add_bookrack?novelUid=1111 HTTP/1.1" 500 19759
[2020-10-27 15:38:58,212] [basehttp.py:124] [basehttp:log_message] [INFO]- "GET /novels/detail/1111 HTTP/1.1" 200 8273
[2020-10-27 15:38:58,276] [basehttp.py:124] [basehttp:log_message] [INFO]- "GET /static/media/novels/58950l.jpg HTTP/1.1" 200 335654
[2020-10-27 15:39:04,450] [exception.py:118] [exception:handle_uncaught_exception] [ERROR]- Internal Server Error: /novels/add_bookrack
Traceback (most recent call last):
  File "D:\Envs\Django2020\lib\site-packages\django\core\handlers\exception.py", line 35, in inner
    response = get_response(request)
  File "D:\Envs\Django2020\lib\site-packages\django\core\handlers\base.py", line 139, in _get_response
    "returned None instead." % (callback.__module__, view_name)
ValueError: The view novels.views.add_bookrack didn't return an HttpResponse object. It returned None instead.
[2020-10-27 15:39:04,466] [basehttp.py:124] [basehttp:log_message] [ERROR]- "GET /novels/add_bookrack?novelUid=1111 HTTP/1.1" 500 19760
[2020-10-27 15:41:24,907] [basehttp.py:124] [basehttp:log_message] [INFO]- "GET /novels/detail/1111 HTTP/1.1" 200 8273
[2020-10-27 15:41:24,940] [basehttp.py:124] [basehttp:log_message] [INFO]- "GET /static/media/novels/58950l.jpg HTTP/1.1" 200 335654
[2020-10-27 15:42:11,137] [exception.py:118] [exception:handle_uncaught_exception] [ERROR]- Internal Server Error: /novels/add_bookrack
Traceback (most recent call last):
  File "D:\Envs\Django2020\lib\site-packages\django\core\handlers\exception.py", line 35, in inner
    response = get_response(request)
  File "D:\Envs\Django2020\lib\site-packages\django\core\handlers\base.py", line 139, in _get_response
    "returned None instead." % (callback.__module__, view_name)
ValueError: The view novels.views.add_bookrack didn't return an HttpResponse object. It returned None instead.
[2020-10-27 15:42:11,158] [basehttp.py:124] [basehttp:log_message] [ERROR]- "GET /novels/add_bookrack?novelUid=1111 HTTP/1.1" 500 20082
[2020-10-27 15:46:49,024] [basehttp.py:124] [basehttp:log_message] [INFO]- "GET /novels/show_bookrack HTTP/1.1" 200 6192
[2020-10-27 15:46:50,443] [views.py:25] [views:index] [INFO]- 缓存中的key为：None----浏览器中的key为:69052fcc182511ebb1fd5800e3fb0696
[2020-10-27 15:46:50,452] [basehttp.py:124] [basehttp:log_message] [INFO]- "GET /novels/index HTTP/1.1" 302 0
[2020-10-27 15:46:50,463] [basehttp.py:124] [basehttp:log_message] [INFO]- "GET /user/login HTTP/1.1" 200 4227
[2020-10-27 15:46:50,500] [basehttp.py:124] [basehttp:log_message] [INFO]- "GET /user/draw HTTP/1.1" 200 2549
[2020-10-27 15:47:00,134] [basehttp.py:124] [basehttp:log_message] [INFO]- "POST /user/login HTTP/1.1" 200 4329
[2020-10-27 15:47:00,170] [basehttp.py:124] [basehttp:log_message] [INFO]- "GET /user/draw HTTP/1.1" 200 2553
[2020-10-27 15:47:09,862] [basehttp.py:124] [basehttp:log_message] [INFO]- "POST /user/login HTTP/1.1" 302 0
[2020-10-27 15:47:09,875] [views.py:25] [views:index] [INFO]- 缓存中的key为：92be4562182811eb864c5800e3fb0696----浏览器中的key为:92be4562182811eb864c5800e3fb0696
[2020-10-27 15:47:09,946] [basehttp.py:124] [basehttp:log_message] [INFO]- "GET /novels/index HTTP/1.1" 200 17963
[2020-10-27 15:47:11,677] [views.py:25] [views:index] [INFO]- 缓存中的key为：92be4562182811eb864c5800e3fb0696----浏览器中的key为:92be4562182811eb864c5800e3fb0696
[2020-10-27 15:47:11,753] [basehttp.py:124] [basehttp:log_message] [INFO]- "GET /novels/index HTTP/1.1" 200 17963
[2020-10-27 15:47:13,737] [basehttp.py:124] [basehttp:log_message] [INFO]- "GET /novels/show_bookrack HTTP/1.1" 200 6192
[2020-10-27 15:47:14,569] [views.py:25] [views:index] [INFO]- 缓存中的key为：92be4562182811eb864c5800e3fb0696----浏览器中的key为:92be4562182811eb864c5800e3fb0696
[2020-10-27 15:47:14,651] [basehttp.py:124] [basehttp:log_message] [INFO]- "GET /novels/index HTTP/1.1" 200 17963
[2020-10-27 15:47:18,917] [basehttp.py:124] [basehttp:log_message] [INFO]- "GET /novels/detail/1111 HTTP/1.1" 200 8273
[2020-10-27 15:47:20,632] [exception.py:118] [exception:handle_uncaught_exception] [ERROR]- Internal Server Error: /novels/add_bookrack
Traceback (most recent call last):
  File "D:\Envs\Django2020\lib\site-packages\django\core\handlers\exception.py", line 35, in inner
    response = get_response(request)
  File "D:\Envs\Django2020\lib\site-packages\django\core\handlers\base.py", line 139, in _get_response
    "returned None instead." % (callback.__module__, view_name)
ValueError: The view novels.views.add_bookrack didn't return an HttpResponse object. It returned None instead.
[2020-10-27 15:47:20,652] [basehttp.py:124] [basehttp:log_message] [ERROR]- "GET /novels/add_bookrack?novelUid=1111 HTTP/1.1" 500 20024
[2020-10-27 15:47:21,725] [exception.py:118] [exception:handle_uncaught_exception] [ERROR]- Internal Server Error: /novels/add_bookrack
Traceback (most recent call last):
  File "D:\Envs\Django2020\lib\site-packages\django\core\handlers\exception.py", line 35, in inner
    response = get_response(request)
  File "D:\Envs\Django2020\lib\site-packages\django\core\handlers\base.py", line 139, in _get_response
    "returned None instead." % (callback.__module__, view_name)
ValueError: The view novels.views.add_bookrack didn't return an HttpResponse object. It returned None instead.
[2020-10-27 15:47:21,737] [basehttp.py:124] [basehttp:log_message] [ERROR]- "GET /novels/add_bookrack?novelUid=1111 HTTP/1.1" 500 20024
[2020-10-27 15:47:33,088] [exception.py:118] [exception:handle_uncaught_exception] [ERROR]- Internal Server Error: /novels/add_bookrack
Traceback (most recent call last):
  File "D:\Envs\Django2020\lib\site-packages\django\core\handlers\exception.py", line 35, in inner
    response = get_response(request)
  File "D:\Envs\Django2020\lib\site-packages\django\core\handlers\base.py", line 139, in _get_response
    "returned None instead." % (callback.__module__, view_name)
ValueError: The view novels.views.add_bookrack didn't return an HttpResponse object. It returned None instead.
[2020-10-27 15:47:33,106] [basehttp.py:124] [basehttp:log_message] [ERROR]- "GET /novels/add_bookrack?novelUid=1111 HTTP/1.1" 500 20082
[2020-10-27 15:47:39,549] [exception.py:118] [exception:handle_uncaught_exception] [ERROR]- Internal Server Error: /novels/add_bookrack
Traceback (most recent call last):
  File "D:\Envs\Django2020\lib\site-packages\django\core\handlers\exception.py", line 35, in inner
    response = get_response(request)
  File "D:\Envs\Django2020\lib\site-packages\django\core\handlers\base.py", line 139, in _get_response
    "returned None instead." % (callback.__module__, view_name)
ValueError: The view novels.views.add_bookrack didn't return an HttpResponse object. It returned None instead.
[2020-10-27 15:47:39,621] [basehttp.py:124] [basehttp:log_message] [ERROR]- "GET /novels/add_bookrack?novelUid=1111 HTTP/1.1" 500 66636
[2020-10-27 15:48:06,309] [exception.py:118] [exception:handle_uncaught_exception] [ERROR]- Internal Server Error: /novels/add_bookrack
Traceback (most recent call last):
  File "D:\Envs\Django2020\lib\site-packages\django\core\handlers\exception.py", line 35, in inner
    response = get_response(request)
  File "D:\Envs\Django2020\lib\site-packages\django\core\handlers\base.py", line 139, in _get_response
    "returned None instead." % (callback.__module__, view_name)
ValueError: The view novels.views.add_bookrack didn't return an HttpResponse object. It returned None instead.
[2020-10-27 15:48:06,356] [basehttp.py:124] [basehttp:log_message] [ERROR]- "GET /novels/add_bookrack?novelUid=1111 HTTP/1.1" 500 66771
[2020-10-27 15:53:11,028] [basehttp.py:124] [basehttp:log_message] [INFO]- "GET /novels/detail/1111 HTTP/1.1" 200 8273
[2020-10-27 15:53:12,598] [exception.py:118] [exception:handle_uncaught_exception] [ERROR]- Internal Server Error: /novels/add_bookrack
Traceback (most recent call last):
  File "D:\Envs\Django2020\lib\site-packages\django\core\handlers\exception.py", line 35, in inner
    response = get_response(request)
  File "D:\Envs\Django2020\lib\site-packages\django\core\handlers\base.py", line 128, in _get_response
    response = self.process_exception_by_middleware(e, request)
  File "D:\Envs\Django2020\lib\site-packages\django\core\handlers\base.py", line 126, in _get_response
    response = wrapped_callback(request, *callback_args, **callback_kwargs)
  File "C:\Users\xinxi\PycharmProjects\Qinxiangshuge\novels\views.py", line 98, in add_bookrack
    return JsonResponse('')
  File "D:\Envs\Django2020\lib\site-packages\django\http\response.py", line 503, in __init__
    'In order to allow non-dict objects to be serialized set the '
TypeError: In order to allow non-dict objects to be serialized set the safe parameter to False.
[2020-10-27 15:53:12,630] [basehttp.py:124] [basehttp:log_message] [ERROR]- "GET /novels/add_bookrack?novelUid=1111 HTTP/1.1" 500 20467
[2020-10-27 15:53:16,254] [exception.py:118] [exception:handle_uncaught_exception] [ERROR]- Internal Server Error: /novels/add_bookrack
Traceback (most recent call last):
  File "D:\Envs\Django2020\lib\site-packages\django\core\handlers\exception.py", line 35, in inner
    response = get_response(request)
  File "D:\Envs\Django2020\lib\site-packages\django\core\handlers\base.py", line 128, in _get_response
    response = self.process_exception_by_middleware(e, request)
  File "D:\Envs\Django2020\lib\site-packages\django\core\handlers\base.py", line 126, in _get_response
    response = wrapped_callback(request, *callback_args, **callback_kwargs)
  File "C:\Users\xinxi\PycharmProjects\Qinxiangshuge\novels\views.py", line 98, in add_bookrack
    return JsonResponse('')
  File "D:\Envs\Django2020\lib\site-packages\django\http\response.py", line 503, in __init__
    'In order to allow non-dict objects to be serialized set the '
TypeError: In order to allow non-dict objects to be serialized set the safe parameter to False.
[2020-10-27 15:53:16,270] [basehttp.py:124] [basehttp:log_message] [ERROR]- "GET /novels/add_bookrack?novelUid=1111 HTTP/1.1" 500 20466
[2020-10-27 15:55:13,377] [basehttp.py:124] [basehttp:log_message] [INFO]- "GET /novels/detail/1111 HTTP/1.1" 200 8273
[2020-10-27 15:55:13,416] [basehttp.py:124] [basehttp:log_message] [INFO]- "GET /static/media/novels/58950l.jpg HTTP/1.1" 200 335654
[2020-10-27 15:55:15,592] [basehttp.py:124] [basehttp:log_message] [INFO]- "GET /novels/detail/1111 HTTP/1.1" 200 8273
[2020-10-27 15:55:15,635] [basehttp.py:124] [basehttp:log_message] [INFO]- "GET /static/media/novels/58950l.jpg HTTP/1.1" 200 335654
[2020-10-27 15:55:18,764] [views.py:25] [views:index] [INFO]- 缓存中的key为：None----浏览器中的key为:92be4562182811eb864c5800e3fb0696
[2020-10-27 15:55:18,775] [basehttp.py:124] [basehttp:log_message] [INFO]- "GET /novels/index HTTP/1.1" 302 0
[2020-10-27 15:55:18,789] [basehttp.py:124] [basehttp:log_message] [INFO]- "GET /user/login HTTP/1.1" 200 4227
[2020-10-27 15:55:18,835] [basehttp.py:124] [basehttp:log_message] [INFO]- "GET /user/draw HTTP/1.1" 200 2620
[2020-10-27 15:55:27,676] [basehttp.py:124] [basehttp:log_message] [INFO]- "POST /user/login HTTP/1.1" 302 0
[2020-10-27 15:55:27,693] [views.py:25] [views:index] [INFO]- 缓存中的key为：c1ba9778182911ebacb75800e3fb0696----浏览器中的key为:c1ba9778182911ebacb75800e3fb0696
[2020-10-27 15:55:27,764] [basehttp.py:124] [basehttp:log_message] [INFO]- "GET /novels/index HTTP/1.1" 200 17963
[2020-10-27 15:55:30,320] [basehttp.py:124] [basehttp:log_message] [INFO]- "GET /novels/detail/1111 HTTP/1.1" 200 8273
[2020-10-27 15:55:32,138] [basehttp.py:124] [basehttp:log_message] [INFO]- "GET /novels/add_bookrack?novelUid=1111 HTTP/1.1" 200 2
[2020-10-27 15:55:45,937] [basehttp.py:124] [basehttp:log_message] [INFO]- "GET /novels/show_bookrack HTTP/1.1" 200 6192
[2020-10-27 15:55:47,427] [views.py:25] [views:index] [INFO]- 缓存中的key为：c1ba9778182911ebacb75800e3fb0696----浏览器中的key为:c1ba9778182911ebacb75800e3fb0696
[2020-10-27 15:55:47,522] [basehttp.py:124] [basehttp:log_message] [INFO]- "GET /novels/index HTTP/1.1" 200 17963
[2020-10-27 15:55:49,561] [basehttp.py:124] [basehttp:log_message] [INFO]- "GET /novels/detail/1111 HTTP/1.1" 200 8273
[2020-10-27 15:55:53,533] [basehttp.py:124] [basehttp:log_message] [INFO]- "GET /novels/add_bookrack?novelUid=1111 HTTP/1.1" 200 2
[2020-10-27 15:55:54,733] [basehttp.py:124] [basehttp:log_message] [INFO]- "GET /novels/add_bookrack?novelUid=1111 HTTP/1.1" 200 2
[2020-10-27 15:55:55,649] [basehttp.py:124] [basehttp:log_message] [INFO]- "GET /novels/add_bookrack?novelUid=1111 HTTP/1.1" 200 2
[2020-10-27 15:55:56,176] [basehttp.py:124] [basehttp:log_message] [INFO]- "GET /novels/add_bookrack?novelUid=1111 HTTP/1.1" 200 2
[2020-10-27 15:55:56,390] [basehttp.py:124] [basehttp:log_message] [INFO]- "GET /novels/add_bookrack?novelUid=1111 HTTP/1.1" 200 2
[2020-10-27 15:57:49,129] [basehttp.py:124] [basehttp:log_message] [INFO]- "GET /novels/add_bookrack?novelUid=1111 HTTP/1.1" 200 2
[2020-10-27 15:57:49,613] [basehttp.py:124] [basehttp:log_message] [INFO]- "GET /novels/add_bookrack?novelUid=1111 HTTP/1.1" 200 2
[2020-10-27 15:57:49,832] [basehttp.py:124] [basehttp:log_message] [INFO]- "GET /novels/add_bookrack?novelUid=1111 HTTP/1.1" 200 2
[2020-10-27 15:57:50,037] [basehttp.py:124] [basehttp:log_message] [INFO]- "GET /novels/add_bookrack?novelUid=1111 HTTP/1.1" 200 2
[2020-10-27 15:57:50,276] [basehttp.py:124] [basehttp:log_message] [INFO]- "GET /novels/add_bookrack?novelUid=1111 HTTP/1.1" 200 2
[2020-10-27 15:57:50,598] [basehttp.py:124] [basehttp:log_message] [INFO]- "GET /novels/add_bookrack?novelUid=1111 HTTP/1.1" 200 2
[2020-10-27 15:57:50,795] [basehttp.py:124] [basehttp:log_message] [INFO]- "GET /novels/add_bookrack?novelUid=1111 HTTP/1.1" 200 2
[2020-10-27 15:57:50,994] [basehttp.py:124] [basehttp:log_message] [INFO]- "GET /novels/add_bookrack?novelUid=1111 HTTP/1.1" 200 2
[2020-10-27 15:57:51,168] [basehttp.py:124] [basehttp:log_message] [INFO]- "GET /novels/add_bookrack?novelUid=1111 HTTP/1.1" 200 2
[2020-10-27 15:58:03,299] [basehttp.py:124] [basehttp:log_message] [INFO]- "GET /novels/show_bookrack HTTP/1.1" 200 6192
[2020-10-27 15:58:38,664] [views.py:25] [views:index] [INFO]- 缓存中的key为：c1ba9778182911ebacb75800e3fb0696----浏览器中的key为:c1ba9778182911ebacb75800e3fb0696
[2020-10-27 15:58:38,854] [basehttp.py:124] [basehttp:log_message] [INFO]- "GET /novels/index HTTP/1.1" 200 17963
[2020-10-27 15:58:46,577] [basehttp.py:124] [basehttp:log_message] [INFO]- "GET /novels/detail/1111 HTTP/1.1" 200 8273
[2020-10-27 15:58:53,278] [basehttp.py:124] [basehttp:log_message] [INFO]- "GET /novels/add_bookrack?novelUid=1111 HTTP/1.1" 200 2
[2020-10-27 15:59:29,768] [views.py:25] [views:index] [INFO]- 缓存中的key为：c1ba9778182911ebacb75800e3fb0696----浏览器中的key为:c1ba9778182911ebacb75800e3fb0696
[2020-10-27 15:59:29,957] [basehttp.py:124] [basehttp:log_message] [INFO]- "GET /novels/index HTTP/1.1" 200 17963
[2020-10-27 15:59:36,301] [basehttp.py:124] [basehttp:log_message] [INFO]- "GET /novels/detail/1111 HTTP/1.1" 200 8273
[2020-10-27 15:59:42,007] [basehttp.py:124] [basehttp:log_message] [INFO]- "GET /novels/add_bookrack?novelUid=1111 HTTP/1.1" 200 2
[2020-10-27 15:59:49,811] [basehttp.py:124] [basehttp:log_message] [INFO]- "GET /novels/add_bookrack?novelUid=1111 HTTP/1.1" 200 2
[2020-10-27 16:09:24,121] [basehttp.py:124] [basehttp:log_message] [INFO]- "GET /novels/detail/1111 HTTP/1.1" 200 8273
[2020-10-27 16:09:25,500] [exception.py:118] [exception:handle_uncaught_exception] [ERROR]- Internal Server Error: /novels/add_bookrack
Traceback (most recent call last):
  File "D:\Envs\Django2020\lib\site-packages\django\core\handlers\exception.py", line 35, in inner
    response = get_response(request)
  File "D:\Envs\Django2020\lib\site-packages\django\core\handlers\base.py", line 128, in _get_response
    response = self.process_exception_by_middleware(e, request)
  File "D:\Envs\Django2020\lib\site-packages\django\core\handlers\base.py", line 126, in _get_response
    response = wrapped_callback(request, *callback_args, **callback_kwargs)
  File "C:\Users\xinxi\PycharmProjects\Qinxiangshuge\novels\views.py", line 89, in add_bookrack
    mybookrack_novel = MyBookrack.objects.filter(user_id=username.uid, novels_id=novel.uid)
AttributeError: 'str' object has no attribute 'uid'
[2020-10-27 16:09:25,518] [basehttp.py:124] [basehttp:log_message] [ERROR]- "GET /novels/add_bookrack?novelUid=1111 HTTP/1.1" 500 20275
[2020-10-27 16:30:07,027] [basehttp.py:124] [basehttp:log_message] [INFO]- "GET /novels/detail/1111 HTTP/1.1" 200 8273
[2020-10-27 16:30:08,808] [exception.py:118] [exception:handle_uncaught_exception] [ERROR]- Internal Server Error: /novels/add_bookrack
Traceback (most recent call last):
  File "D:\Envs\Django2020\lib\site-packages\django\core\handlers\exception.py", line 35, in inner
    response = get_response(request)
  File "D:\Envs\Django2020\lib\site-packages\django\core\handlers\base.py", line 128, in _get_response
    response = self.process_exception_by_middleware(e, request)
  File "D:\Envs\Django2020\lib\site-packages\django\core\handlers\base.py", line 126, in _get_response
    response = wrapped_callback(request, *callback_args, **callback_kwargs)
  File "C:\Users\xinxi\PycharmProjects\Qinxiangshuge\novels\views.py", line 90, in add_bookrack
    mybookrack_novel = MyBookrack.objects.filter(user_id=username.uid, novels_id=novel.uid)
AttributeError: 'str' object has no attribute 'uid'
[2020-10-27 16:30:08,829] [basehttp.py:124] [basehttp:log_message] [ERROR]- "GET /novels/add_bookrack?novelUid=1111 HTTP/1.1" 500 20276
[2020-10-27 16:33:40,807] [exception.py:118] [exception:handle_uncaught_exception] [ERROR]- Internal Server Error: /novels/add_bookrack
Traceback (most recent call last):
  File "D:\Envs\Django2020\lib\site-packages\django\core\handlers\exception.py", line 35, in inner
    response = get_response(request)
  File "D:\Envs\Django2020\lib\site-packages\django\core\handlers\base.py", line 128, in _get_response
    response = self.process_exception_by_middleware(e, request)
  File "D:\Envs\Django2020\lib\site-packages\django\core\handlers\base.py", line 126, in _get_response
    response = wrapped_callback(request, *callback_args, **callback_kwargs)
  File "C:\Users\xinxi\PycharmProjects\Qinxiangshuge\novels\views.py", line 90, in add_bookrack
    useruid=username.uid
AttributeError: 'str' object has no attribute 'uid'
[2020-10-27 16:33:40,930] [basehttp.py:124] [basehttp:log_message] [ERROR]- "GET /novels/add_bookrack?novelUid=1111 HTTP/1.1" 500 20209
[2020-10-27 16:35:49,528] [basehttp.py:124] [basehttp:log_message] [INFO]- "GET /novels/detail/1111 HTTP/1.1" 200 8273
[2020-10-27 16:35:51,116] [exception.py:118] [exception:handle_uncaught_exception] [ERROR]- Internal Server Error: /novels/add_bookrack
Traceback (most recent call last):
  File "D:\Envs\Django2020\lib\site-packages\django\core\handlers\exception.py", line 35, in inner
    response = get_response(request)
  File "D:\Envs\Django2020\lib\site-packages\django\core\handlers\base.py", line 128, in _get_response
    response = self.process_exception_by_middleware(e, request)
  File "D:\Envs\Django2020\lib\site-packages\django\core\handlers\base.py", line 126, in _get_response
    response = wrapped_callback(request, *callback_args, **callback_kwargs)
  File "C:\Users\xinxi\PycharmProjects\Qinxiangshuge\novels\views.py", line 92, in add_bookrack
    mybookrack_novel = MyBookrack.objects.filter(user_id=user.uid, novels_id=novel.uid)
AttributeError: 'QuerySet' object has no attribute 'uid'
[2020-10-27 16:35:51,141] [basehttp.py:124] [basehttp:log_message] [ERROR]- "GET /novels/add_bookrack?novelUid=1111 HTTP/1.1" 500 20282
[2020-10-27 16:37:29,419] [basehttp.py:124] [basehttp:log_message] [INFO]- "GET /novels/detail/1111 HTTP/1.1" 200 8273
[2020-10-27 16:37:34,845] [exception.py:118] [exception:handle_uncaught_exception] [ERROR]- Internal Server Error: /novels/add_bookrack
Traceback (most recent call last):
  File "D:\Envs\Django2020\lib\site-packages\django\core\handlers\exception.py", line 35, in inner
    response = get_response(request)
  File "D:\Envs\Django2020\lib\site-packages\django\core\handlers\base.py", line 128, in _get_response
    response = self.process_exception_by_middleware(e, request)
  File "D:\Envs\Django2020\lib\site-packages\django\core\handlers\base.py", line 126, in _get_response
    response = wrapped_callback(request, *callback_args, **callback_kwargs)
  File "C:\Users\xinxi\PycharmProjects\Qinxiangshuge\novels\views.py", line 97, in add_bookrack
    mybookrack = MyBookrack.objects.create(novel_id=novel.uid, user_id=username.uid)
AttributeError: 'str' object has no attribute 'uid'
[2020-10-27 16:37:34,871] [basehttp.py:124] [basehttp:log_message] [ERROR]- "GET /novels/add_bookrack?novelUid=1111 HTTP/1.1" 500 20273
[2020-10-27 16:38:07,544] [basehttp.py:124] [basehttp:log_message] [INFO]- "GET /novels/detail/1111 HTTP/1.1" 200 8273
[2020-10-27 16:38:08,826] [exception.py:118] [exception:handle_uncaught_exception] [ERROR]- Internal Server Error: /novels/add_bookrack
Traceback (most recent call last):
  File "D:\Envs\Django2020\lib\site-packages\django\core\handlers\exception.py", line 35, in inner
    response = get_response(request)
  File "D:\Envs\Django2020\lib\site-packages\django\core\handlers\base.py", line 128, in _get_response
    response = self.process_exception_by_middleware(e, request)
  File "D:\Envs\Django2020\lib\site-packages\django\core\handlers\base.py", line 126, in _get_response
    response = wrapped_callback(request, *callback_args, **callback_kwargs)
  File "C:\Users\xinxi\PycharmProjects\Qinxiangshuge\novels\views.py", line 96, in add_bookrack
    mybookrack = MyBookrack.objects.create(novel_id=novel.uid, user_id=user.uid)
  File "D:\Envs\Django2020\lib\site-packages\django\db\models\manager.py", line 82, in manager_method
    return getattr(self.get_queryset(), name)(*args, **kwargs)
  File "D:\Envs\Django2020\lib\site-packages\django\db\models\query.py", line 415, in create
    obj = self.model(**kwargs)
  File "D:\Envs\Django2020\lib\site-packages\django\db\models\base.py", line 495, in __init__
    raise TypeError("'%s' is an invalid keyword argument for this function" % kwarg)
TypeError: 'novel_id' is an invalid keyword argument for this function
[2020-10-27 16:38:08,861] [basehttp.py:124] [basehttp:log_message] [ERROR]- "GET /novels/add_bookrack?novelUid=1111 HTTP/1.1" 500 20788
[2020-10-27 17:37:25,392] [basehttp.py:124] [basehttp:log_message] [INFO]- "GET /novels/detail/1111 HTTP/1.1" 200 8273
[2020-10-27 17:37:27,584] [exception.py:118] [exception:handle_uncaught_exception] [ERROR]- Internal Server Error: /novels/add_bookrack
Traceback (most recent call last):
  File "D:\Envs\Django2020\lib\site-packages\django\core\handlers\exception.py", line 35, in inner
    response = get_response(request)
  File "D:\Envs\Django2020\lib\site-packages\django\core\handlers\base.py", line 128, in _get_response
    response = self.process_exception_by_middleware(e, request)
  File "D:\Envs\Django2020\lib\site-packages\django\core\handlers\base.py", line 126, in _get_response
    response = wrapped_callback(request, *callback_args, **callback_kwargs)
  File "C:\Users\xinxi\PycharmProjects\Qinxiangshuge\novels\views.py", line 90, in add_bookrack
    mybookrack_novel = MyBookrack.objects.filter(user_id=user.uid, novels_id=d)
NameError: name 'd' is not defined
[2020-10-27 17:37:27,601] [basehttp.py:124] [basehttp:log_message] [ERROR]- "GET /novels/add_bookrack?novelUid=1111 HTTP/1.1" 500 20229
[2020-10-27 17:37:50,182] [basehttp.py:124] [basehttp:log_message] [INFO]- "GET /novels/detail/1111 HTTP/1.1" 200 8273
[2020-10-27 17:37:51,346] [exception.py:118] [exception:handle_uncaught_exception] [ERROR]- Internal Server Error: /novels/add_bookrack
Traceback (most recent call last):
  File "D:\Envs\Django2020\lib\site-packages\django\core\handlers\exception.py", line 35, in inner
    response = get_response(request)
  File "D:\Envs\Django2020\lib\site-packages\django\core\handlers\base.py", line 128, in _get_response
    response = self.process_exception_by_middleware(e, request)
  File "D:\Envs\Django2020\lib\site-packages\django\core\handlers\base.py", line 126, in _get_response
    response = wrapped_callback(request, *callback_args, **callback_kwargs)
  File "C:\Users\xinxi\PycharmProjects\Qinxiangshuge\novels\views.py", line 95, in add_bookrack
    mybookrack = MyBookrack.objects.create(novel_id=uid, user_id=user.uid)
  File "D:\Envs\Django2020\lib\site-packages\django\db\models\manager.py", line 82, in manager_method
    return getattr(self.get_queryset(), name)(*args, **kwargs)
  File "D:\Envs\Django2020\lib\site-packages\django\db\models\query.py", line 415, in create
    obj = self.model(**kwargs)
  File "D:\Envs\Django2020\lib\site-packages\django\db\models\base.py", line 495, in __init__
    raise TypeError("'%s' is an invalid keyword argument for this function" % kwarg)
TypeError: 'novel_id' is an invalid keyword argument for this function
[2020-10-27 17:37:51,378] [basehttp.py:124] [basehttp:log_message] [ERROR]- "GET /novels/add_bookrack?novelUid=1111 HTTP/1.1" 500 20782
[2020-10-27 17:38:09,529] [basehttp.py:124] [basehttp:log_message] [INFO]- "GET /novels/detail/1111 HTTP/1.1" 200 8273
[2020-10-27 17:38:09,911] [basehttp.py:124] [basehttp:log_message] [INFO]- "GET /novels/detail/1111 HTTP/1.1" 200 8273
[2020-10-27 17:38:11,148] [exception.py:118] [exception:handle_uncaught_exception] [ERROR]- Internal Server Error: /novels/add_bookrack
Traceback (most recent call last):
  File "D:\Envs\Django2020\lib\site-packages\django\db\backends\mysql\base.py", line 71, in execute
    return self.cursor.execute(query, args)
  File "D:\Envs\Django2020\lib\site-packages\MySQLdb\cursors.py", line 209, in execute
    res = self._query(query)
  File "D:\Envs\Django2020\lib\site-packages\MySQLdb\cursors.py", line 315, in _query
    db.query(q)
  File "D:\Envs\Django2020\lib\site-packages\MySQLdb\connections.py", line 239, in query
    _mysql.connection.query(self, query)
MySQLdb._exceptions.OperationalError: (1048, "Column 'chapters_id' cannot be null")

During handling of the above exception, another exception occurred:

Traceback (most recent call last):
  File "D:\Envs\Django2020\lib\site-packages\django\core\handlers\exception.py", line 35, in inner
    response = get_response(request)
  File "D:\Envs\Django2020\lib\site-packages\django\core\handlers\base.py", line 128, in _get_response
    response = self.process_exception_by_middleware(e, request)
  File "D:\Envs\Django2020\lib\site-packages\django\core\handlers\base.py", line 126, in _get_response
    response = wrapped_callback(request, *callback_args, **callback_kwargs)
  File "C:\Users\xinxi\PycharmProjects\Qinxiangshuge\novels\views.py", line 95, in add_bookrack
    mybookrack = MyBookrack.objects.create(novels_id=uid, user_id=user.uid)
  File "D:\Envs\Django2020\lib\site-packages\django\db\models\manager.py", line 82, in manager_method
    return getattr(self.get_queryset(), name)(*args, **kwargs)
  File "D:\Envs\Django2020\lib\site-packages\django\db\models\query.py", line 417, in create
    obj.save(force_insert=True, using=self.db)
  File "D:\Envs\Django2020\lib\site-packages\django\db\models\base.py", line 729, in save
    force_update=force_update, update_fields=update_fields)
  File "D:\Envs\Django2020\lib\site-packages\django\db\models\base.py", line 759, in save_base
    updated = self._save_table(raw, cls, force_insert, force_update, using, update_fields)
  File "D:\Envs\Django2020\lib\site-packages\django\db\models\base.py", line 842, in _save_table
    result = self._do_insert(cls._base_manager, using, fields, update_pk, raw)
  File "D:\Envs\Django2020\lib\site-packages\django\db\models\base.py", line 880, in _do_insert
    using=using, raw=raw)
  File "D:\Envs\Django2020\lib\site-packages\django\db\models\manager.py", line 82, in manager_method
    return getattr(self.get_queryset(), name)(*args, **kwargs)
  File "D:\Envs\Django2020\lib\site-packages\django\db\models\query.py", line 1125, in _insert
    return query.get_compiler(using=using).execute_sql(return_id)
  File "D:\Envs\Django2020\lib\site-packages\django\db\models\sql\compiler.py", line 1280, in execute_sql
    cursor.execute(sql, params)
  File "D:\Envs\Django2020\lib\site-packages\django\db\backends\utils.py", line 100, in execute
    return super().execute(sql, params)
  File "D:\Envs\Django2020\lib\site-packages\django\db\backends\utils.py", line 68, in execute
    return self._execute_with_wrappers(sql, params, many=False, executor=self._execute)
  File "D:\Envs\Django2020\lib\site-packages\django\db\backends\utils.py", line 77, in _execute_with_wrappers
    return executor(sql, params, many, context)
  File "D:\Envs\Django2020\lib\site-packages\django\db\backends\utils.py", line 85, in _execute
    return self.cursor.execute(sql, params)
  File "D:\Envs\Django2020\lib\site-packages\django\db\backends\mysql\base.py", line 76, in execute
    raise utils.IntegrityError(*tuple(e.args))
django.db.utils.IntegrityError: (1048, "Column 'chapters_id' cannot be null")
[2020-10-27 17:38:11,200] [basehttp.py:124] [basehttp:log_message] [ERROR]- "GET /novels/add_bookrack?novelUid=1111 HTTP/1.1" 500 23136
[2020-10-27 17:46:55,509] [basehttp.py:124] [basehttp:log_message] [INFO]- "GET /novels/detail/1111 HTTP/1.1" 200 8273
[2020-10-27 17:46:56,694] [exception.py:118] [exception:handle_uncaught_exception] [ERROR]- Internal Server Error: /novels/add_bookrack
Traceback (most recent call last):
  File "D:\Envs\Django2020\lib\site-packages\django\core\handlers\exception.py", line 35, in inner
    response = get_response(request)
  File "D:\Envs\Django2020\lib\site-packages\django\core\handlers\base.py", line 128, in _get_response
    response = self.process_exception_by_middleware(e, request)
  File "D:\Envs\Django2020\lib\site-packages\django\core\handlers\base.py", line 126, in _get_response
    response = wrapped_callback(request, *callback_args, **callback_kwargs)
  File "C:\Users\xinxi\PycharmProjects\Qinxiangshuge\novels\views.py", line 87, in add_bookrack
    uid = chapter.uid
AttributeError: 'QuerySet' object has no attribute 'uid'
[2020-10-27 17:46:56,723] [basehttp.py:124] [basehttp:log_message] [ERROR]- "GET /novels/add_bookrack?novelUid=1111 HTTP/1.1" 500 20216
[2020-10-27 17:52:15,682] [basehttp.py:124] [basehttp:log_message] [INFO]- "GET /novels/detail/1111 HTTP/1.1" 200 8273
[2020-10-27 17:52:38,222] [exception.py:118] [exception:handle_uncaught_exception] [ERROR]- Internal Server Error: /novels/add_bookrack
Traceback (most recent call last):
  File "D:\Envs\Django2020\lib\site-packages\django\core\handlers\exception.py", line 35, in inner
    response = get_response(request)
  File "D:\Envs\Django2020\lib\site-packages\django\core\handlers\base.py", line 128, in _get_response
    response = self.process_exception_by_middleware(e, request)
  File "D:\Envs\Django2020\lib\site-packages\django\core\handlers\base.py", line 126, in _get_response
    response = wrapped_callback(request, *callback_args, **callback_kwargs)
  File "C:\Users\xinxi\PycharmProjects\Qinxiangshuge\novels\views.py", line 88, in add_bookrack
    uid = chapter.uid
AttributeError: 'QuerySet' object has no attribute 'uid'
[2020-10-27 17:52:38,268] [basehttp.py:124] [basehttp:log_message] [ERROR]- "GET /novels/add_bookrack?novelUid=1111 HTTP/1.1" 500 20216
[2020-10-27 17:55:17,703] [basehttp.py:124] [basehttp:log_message] [INFO]- "GET /novels/show_bookrack HTTP/1.1" 200 6192
[2020-10-27 18:09:04,219] [basehttp.py:124] [basehttp:log_message] [INFO]- "GET /novels/show_bookrack HTTP/1.1" 200 6192
[2020-10-27 18:09:08,163] [basehttp.py:124] [basehttp:log_message] [INFO]- "GET /novels/detail/1111 HTTP/1.1" 200 8273
[2020-10-27 18:09:09,194] [exception.py:118] [exception:handle_uncaught_exception] [ERROR]- Internal Server Error: /novels/add_bookrack
Traceback (most recent call last):
  File "D:\Envs\Django2020\lib\site-packages\django\db\backends\mysql\base.py", line 71, in execute
    return self.cursor.execute(query, args)
  File "D:\Envs\Django2020\lib\site-packages\MySQLdb\cursors.py", line 209, in execute
    res = self._query(query)
  File "D:\Envs\Django2020\lib\site-packages\MySQLdb\cursors.py", line 315, in _query
    db.query(q)
  File "D:\Envs\Django2020\lib\site-packages\MySQLdb\connections.py", line 239, in query
    _mysql.connection.query(self, query)
MySQLdb._exceptions.OperationalError: (1048, "Column 'chapters_id' cannot be null")

During handling of the above exception, another exception occurred:

Traceback (most recent call last):
  File "D:\Envs\Django2020\lib\site-packages\django\core\handlers\exception.py", line 35, in inner
    response = get_response(request)
  File "D:\Envs\Django2020\lib\site-packages\django\core\handlers\base.py", line 128, in _get_response
    response = self.process_exception_by_middleware(e, request)
  File "D:\Envs\Django2020\lib\site-packages\django\core\handlers\base.py", line 126, in _get_response
    response = wrapped_callback(request, *callback_args, **callback_kwargs)
  File "C:\Users\xinxi\PycharmProjects\Qinxiangshuge\novels\views.py", line 97, in add_bookrack
    mybookrack = MyBookrack.objects.create(novels_id=uid, user_id=user.uid,chapters_id=None)
  File "D:\Envs\Django2020\lib\site-packages\django\db\models\manager.py", line 82, in manager_method
    return getattr(self.get_queryset(), name)(*args, **kwargs)
  File "D:\Envs\Django2020\lib\site-packages\django\db\models\query.py", line 417, in create
    obj.save(force_insert=True, using=self.db)
  File "D:\Envs\Django2020\lib\site-packages\django\db\models\base.py", line 729, in save
    force_update=force_update, update_fields=update_fields)
  File "D:\Envs\Django2020\lib\site-packages\django\db\models\base.py", line 759, in save_base
    updated = self._save_table(raw, cls, force_insert, force_update, using, update_fields)
  File "D:\Envs\Django2020\lib\site-packages\django\db\models\base.py", line 842, in _save_table
    result = self._do_insert(cls._base_manager, using, fields, update_pk, raw)
  File "D:\Envs\Django2020\lib\site-packages\django\db\models\base.py", line 880, in _do_insert
    using=using, raw=raw)
  File "D:\Envs\Django2020\lib\site-packages\django\db\models\manager.py", line 82, in manager_method
    return getattr(self.get_queryset(), name)(*args, **kwargs)
  File "D:\Envs\Django2020\lib\site-packages\django\db\models\query.py", line 1125, in _insert
    return query.get_compiler(using=using).execute_sql(return_id)
  File "D:\Envs\Django2020\lib\site-packages\django\db\models\sql\compiler.py", line 1280, in execute_sql
    cursor.execute(sql, params)
  File "D:\Envs\Django2020\lib\site-packages\django\db\backends\utils.py", line 100, in execute
    return super().execute(sql, params)
  File "D:\Envs\Django2020\lib\site-packages\django\db\backends\utils.py", line 68, in execute
    return self._execute_with_wrappers(sql, params, many=False, executor=self._execute)
  File "D:\Envs\Django2020\lib\site-packages\django\db\backends\utils.py", line 77, in _execute_with_wrappers
    return executor(sql, params, many, context)
  File "D:\Envs\Django2020\lib\site-packages\django\db\backends\utils.py", line 85, in _execute
    return self.cursor.execute(sql, params)
  File "D:\Envs\Django2020\lib\site-packages\django\db\backends\mysql\base.py", line 76, in execute
    raise utils.IntegrityError(*tuple(e.args))
django.db.utils.IntegrityError: (1048, "Column 'chapters_id' cannot be null")
[2020-10-27 18:09:09,321] [basehttp.py:124] [basehttp:log_message] [ERROR]- "GET /novels/add_bookrack?novelUid=1111 HTTP/1.1" 500 23152
[2020-10-27 18:11:29,193] [basehttp.py:124] [basehttp:log_message] [INFO]- "GET /novels/novelbody/44444444 HTTP/1.1" 200 13046
[2020-10-27 18:11:47,171] [basehttp.py:124] [basehttp:log_message] [INFO]- "GET /novels/show_bookrack HTTP/1.1" 200 6192
[2020-10-27 18:18:20,751] [basehttp.py:124] [basehttp:log_message] [INFO]- "GET /novels/show_bookrack HTTP/1.1" 200 6192
[2020-10-27 18:18:24,602] [basehttp.py:124] [basehttp:log_message] [INFO]- "GET /novels/detail/1111 HTTP/1.1" 200 8273
[2020-10-27 18:18:27,810] [views.py:23] [views:index] [INFO]- 缓存中的key为：None----浏览器中的key为:c1ba9778182911ebacb75800e3fb0696
[2020-10-27 18:18:27,819] [basehttp.py:124] [basehttp:log_message] [INFO]- "GET /novels/index HTTP/1.1" 302 0
[2020-10-27 18:18:27,847] [basehttp.py:124] [basehttp:log_message] [INFO]- "GET /user/login HTTP/1.1" 200 4227
[2020-10-27 18:18:27,905] [basehttp.py:124] [basehttp:log_message] [INFO]- "GET /user/draw HTTP/1.1" 200 2423
[2020-10-27 18:18:33,180] [basehttp.py:124] [basehttp:log_message] [INFO]- "GET /user/draw?ran=0.4862359723905525 HTTP/1.1" 200 2905
[2020-10-27 18:18:37,987] [basehttp.py:124] [basehttp:log_message] [INFO]- "POST /user/login HTTP/1.1" 302 0
[2020-10-27 18:18:38,002] [views.py:23] [views:index] [INFO]- 缓存中的key为：c134d966183d11ebb79a5800e3fb0696----浏览器中的key为:c134d966183d11ebb79a5800e3fb0696
[2020-10-27 18:18:38,088] [basehttp.py:124] [basehttp:log_message] [INFO]- "GET /novels/index HTTP/1.1" 200 17963
[2020-10-27 18:18:40,364] [basehttp.py:124] [basehttp:log_message] [INFO]- "GET /novels/detail/1111 HTTP/1.1" 200 8273
[2020-10-27 18:18:41,865] [exception.py:118] [exception:handle_uncaught_exception] [ERROR]- Internal Server Error: /novels/add_bookrack
Traceback (most recent call last):
  File "D:\Envs\Django2020\lib\site-packages\django\db\backends\mysql\base.py", line 71, in execute
    return self.cursor.execute(query, args)
  File "D:\Envs\Django2020\lib\site-packages\MySQLdb\cursors.py", line 209, in execute
    res = self._query(query)
  File "D:\Envs\Django2020\lib\site-packages\MySQLdb\cursors.py", line 315, in _query
    db.query(q)
  File "D:\Envs\Django2020\lib\site-packages\MySQLdb\connections.py", line 239, in query
    _mysql.connection.query(self, query)
MySQLdb._exceptions.OperationalError: (1048, "Column 'chapters_uid' cannot be null")

During handling of the above exception, another exception occurred:

Traceback (most recent call last):
  File "D:\Envs\Django2020\lib\site-packages\django\core\handlers\exception.py", line 35, in inner
    response = get_response(request)
  File "D:\Envs\Django2020\lib\site-packages\django\core\handlers\base.py", line 128, in _get_response
    response = self.process_exception_by_middleware(e, request)
  File "D:\Envs\Django2020\lib\site-packages\django\core\handlers\base.py", line 126, in _get_response
    response = wrapped_callback(request, *callback_args, **callback_kwargs)
  File "C:\Users\xinxi\PycharmProjects\Qinxiangshuge\novels\views.py", line 97, in add_bookrack
    mybookrack = MyBookrack.objects.create(novels_id=uid, user_id=user.uid)
  File "D:\Envs\Django2020\lib\site-packages\django\db\models\manager.py", line 82, in manager_method
    return getattr(self.get_queryset(), name)(*args, **kwargs)
  File "D:\Envs\Django2020\lib\site-packages\django\db\models\query.py", line 417, in create
    obj.save(force_insert=True, using=self.db)
  File "D:\Envs\Django2020\lib\site-packages\django\db\models\base.py", line 729, in save
    force_update=force_update, update_fields=update_fields)
  File "D:\Envs\Django2020\lib\site-packages\django\db\models\base.py", line 759, in save_base
    updated = self._save_table(raw, cls, force_insert, force_update, using, update_fields)
  File "D:\Envs\Django2020\lib\site-packages\django\db\models\base.py", line 842, in _save_table
    result = self._do_insert(cls._base_manager, using, fields, update_pk, raw)
  File "D:\Envs\Django2020\lib\site-packages\django\db\models\base.py", line 880, in _do_insert
    using=using, raw=raw)
  File "D:\Envs\Django2020\lib\site-packages\django\db\models\manager.py", line 82, in manager_method
    return getattr(self.get_queryset(), name)(*args, **kwargs)
  File "D:\Envs\Django2020\lib\site-packages\django\db\models\query.py", line 1125, in _insert
    return query.get_compiler(using=using).execute_sql(return_id)
  File "D:\Envs\Django2020\lib\site-packages\django\db\models\sql\compiler.py", line 1280, in execute_sql
    cursor.execute(sql, params)
  File "D:\Envs\Django2020\lib\site-packages\django\db\backends\utils.py", line 100, in execute
    return super().execute(sql, params)
  File "D:\Envs\Django2020\lib\site-packages\django\db\backends\utils.py", line 68, in execute
    return self._execute_with_wrappers(sql, params, many=False, executor=self._execute)
  File "D:\Envs\Django2020\lib\site-packages\django\db\backends\utils.py", line 77, in _execute_with_wrappers
    return executor(sql, params, many, context)
  File "D:\Envs\Django2020\lib\site-packages\django\db\backends\utils.py", line 85, in _execute
    return self.cursor.execute(sql, params)
  File "D:\Envs\Django2020\lib\site-packages\django\db\backends\mysql\base.py", line 76, in execute
    raise utils.IntegrityError(*tuple(e.args))
django.db.utils.IntegrityError: (1048, "Column 'chapters_uid' cannot be null")
[2020-10-27 18:18:41,909] [basehttp.py:124] [basehttp:log_message] [ERROR]- "GET /novels/add_bookrack?novelUid=1111 HTTP/1.1" 500 23139
[2020-10-27 18:18:43,900] [exception.py:118] [exception:handle_uncaught_exception] [ERROR]- Internal Server Error: /novels/add_bookrack
Traceback (most recent call last):
  File "D:\Envs\Django2020\lib\site-packages\django\db\backends\mysql\base.py", line 71, in execute
    return self.cursor.execute(query, args)
  File "D:\Envs\Django2020\lib\site-packages\MySQLdb\cursors.py", line 209, in execute
    res = self._query(query)
  File "D:\Envs\Django2020\lib\site-packages\MySQLdb\cursors.py", line 315, in _query
    db.query(q)
  File "D:\Envs\Django2020\lib\site-packages\MySQLdb\connections.py", line 239, in query
    _mysql.connection.query(self, query)
MySQLdb._exceptions.OperationalError: (1048, "Column 'chapters_uid' cannot be null")

During handling of the above exception, another exception occurred:

Traceback (most recent call last):
  File "D:\Envs\Django2020\lib\site-packages\django\core\handlers\exception.py", line 35, in inner
    response = get_response(request)
  File "D:\Envs\Django2020\lib\site-packages\django\core\handlers\base.py", line 128, in _get_response
    response = self.process_exception_by_middleware(e, request)
  File "D:\Envs\Django2020\lib\site-packages\django\core\handlers\base.py", line 126, in _get_response
    response = wrapped_callback(request, *callback_args, **callback_kwargs)
  File "C:\Users\xinxi\PycharmProjects\Qinxiangshuge\novels\views.py", line 97, in add_bookrack
    mybookrack = MyBookrack.objects.create(novels_id=uid, user_id=user.uid)
  File "D:\Envs\Django2020\lib\site-packages\django\db\models\manager.py", line 82, in manager_method
    return getattr(self.get_queryset(), name)(*args, **kwargs)
  File "D:\Envs\Django2020\lib\site-packages\django\db\models\query.py", line 417, in create
    obj.save(force_insert=True, using=self.db)
  File "D:\Envs\Django2020\lib\site-packages\django\db\models\base.py", line 729, in save
    force_update=force_update, update_fields=update_fields)
  File "D:\Envs\Django2020\lib\site-packages\django\db\models\base.py", line 759, in save_base
    updated = self._save_table(raw, cls, force_insert, force_update, using, update_fields)
  File "D:\Envs\Django2020\lib\site-packages\django\db\models\base.py", line 842, in _save_table
    result = self._do_insert(cls._base_manager, using, fields, update_pk, raw)
  File "D:\Envs\Django2020\lib\site-packages\django\db\models\base.py", line 880, in _do_insert
    using=using, raw=raw)
  File "D:\Envs\Django2020\lib\site-packages\django\db\models\manager.py", line 82, in manager_method
    return getattr(self.get_queryset(), name)(*args, **kwargs)
  File "D:\Envs\Django2020\lib\site-packages\django\db\models\query.py", line 1125, in _insert
    return query.get_compiler(using=using).execute_sql(return_id)
  File "D:\Envs\Django2020\lib\site-packages\django\db\models\sql\compiler.py", line 1280, in execute_sql
    cursor.execute(sql, params)
  File "D:\Envs\Django2020\lib\site-packages\django\db\backends\utils.py", line 100, in execute
    return super().execute(sql, params)
  File "D:\Envs\Django2020\lib\site-packages\django\db\backends\utils.py", line 68, in execute
    return self._execute_with_wrappers(sql, params, many=False, executor=self._execute)
  File "D:\Envs\Django2020\lib\site-packages\django\db\backends\utils.py", line 77, in _execute_with_wrappers
    return executor(sql, params, many, context)
  File "D:\Envs\Django2020\lib\site-packages\django\db\backends\utils.py", line 85, in _execute
    return self.cursor.execute(sql, params)
  File "D:\Envs\Django2020\lib\site-packages\django\db\backends\mysql\base.py", line 76, in execute
    raise utils.IntegrityError(*tuple(e.args))
django.db.utils.IntegrityError: (1048, "Column 'chapters_uid' cannot be null")
[2020-10-27 18:18:43,928] [basehttp.py:124] [basehttp:log_message] [ERROR]- "GET /novels/add_bookrack?novelUid=1111 HTTP/1.1" 500 23138
[2020-10-27 18:20:44,880] [views.py:23] [views:index] [INFO]- 缓存中的key为：c134d966183d11ebb79a5800e3fb0696----浏览器中的key为:c134d966183d11ebb79a5800e3fb0696
[2020-10-27 18:20:45,087] [basehttp.py:124] [basehttp:log_message] [INFO]- "GET /novels/index HTTP/1.1" 200 17963
[2020-10-27 18:20:47,252] [basehttp.py:124] [basehttp:log_message] [INFO]- "GET /novels/detail/1111 HTTP/1.1" 200 8273
[2020-10-27 18:20:49,019] [exception.py:118] [exception:handle_uncaught_exception] [ERROR]- Internal Server Error: /novels/add_bookrack
Traceback (most recent call last):
  File "D:\Envs\Django2020\lib\site-packages\django\db\backends\mysql\base.py", line 71, in execute
    return self.cursor.execute(query, args)
  File "D:\Envs\Django2020\lib\site-packages\MySQLdb\cursors.py", line 209, in execute
    res = self._query(query)
  File "D:\Envs\Django2020\lib\site-packages\MySQLdb\cursors.py", line 315, in _query
    db.query(q)
  File "D:\Envs\Django2020\lib\site-packages\MySQLdb\connections.py", line 239, in query
    _mysql.connection.query(self, query)
MySQLdb._exceptions.OperationalError: (1048, "Column 'chapters_uid' cannot be null")

During handling of the above exception, another exception occurred:

Traceback (most recent call last):
  File "D:\Envs\Django2020\lib\site-packages\django\core\handlers\exception.py", line 35, in inner
    response = get_response(request)
  File "D:\Envs\Django2020\lib\site-packages\django\core\handlers\base.py", line 128, in _get_response
    response = self.process_exception_by_middleware(e, request)
  File "D:\Envs\Django2020\lib\site-packages\django\core\handlers\base.py", line 126, in _get_response
    response = wrapped_callback(request, *callback_args, **callback_kwargs)
  File "C:\Users\xinxi\PycharmProjects\Qinxiangshuge\novels\views.py", line 95, in add_bookrack
    mybookrack = MyBookrack.objects.create(novels_id=uid, user_id=user.uid)
  File "D:\Envs\Django2020\lib\site-packages\django\db\models\manager.py", line 82, in manager_method
    return getattr(self.get_queryset(), name)(*args, **kwargs)
  File "D:\Envs\Django2020\lib\site-packages\django\db\models\query.py", line 417, in create
    obj.save(force_insert=True, using=self.db)
  File "D:\Envs\Django2020\lib\site-packages\django\db\models\base.py", line 729, in save
    force_update=force_update, update_fields=update_fields)
  File "D:\Envs\Django2020\lib\site-packages\django\db\models\base.py", line 759, in save_base
    updated = self._save_table(raw, cls, force_insert, force_update, using, update_fields)
  File "D:\Envs\Django2020\lib\site-packages\django\db\models\base.py", line 842, in _save_table
    result = self._do_insert(cls._base_manager, using, fields, update_pk, raw)
  File "D:\Envs\Django2020\lib\site-packages\django\db\models\base.py", line 880, in _do_insert
    using=using, raw=raw)
  File "D:\Envs\Django2020\lib\site-packages\django\db\models\manager.py", line 82, in manager_method
    return getattr(self.get_queryset(), name)(*args, **kwargs)
  File "D:\Envs\Django2020\lib\site-packages\django\db\models\query.py", line 1125, in _insert
    return query.get_compiler(using=using).execute_sql(return_id)
  File "D:\Envs\Django2020\lib\site-packages\django\db\models\sql\compiler.py", line 1280, in execute_sql
    cursor.execute(sql, params)
  File "D:\Envs\Django2020\lib\site-packages\django\db\backends\utils.py", line 100, in execute
    return super().execute(sql, params)
  File "D:\Envs\Django2020\lib\site-packages\django\db\backends\utils.py", line 68, in execute
    return self._execute_with_wrappers(sql, params, many=False, executor=self._execute)
  File "D:\Envs\Django2020\lib\site-packages\django\db\backends\utils.py", line 77, in _execute_with_wrappers
    return executor(sql, params, many, context)
  File "D:\Envs\Django2020\lib\site-packages\django\db\backends\utils.py", line 85, in _execute
    return self.cursor.execute(sql, params)
  File "D:\Envs\Django2020\lib\site-packages\django\db\backends\mysql\base.py", line 76, in execute
    raise utils.IntegrityError(*tuple(e.args))
django.db.utils.IntegrityError: (1048, "Column 'chapters_uid' cannot be null")
[2020-10-27 18:20:49,059] [basehttp.py:124] [basehttp:log_message] [ERROR]- "GET /novels/add_bookrack?novelUid=1111 HTTP/1.1" 500 23139
[2020-10-27 18:24:48,267] [basehttp.py:124] [basehttp:log_message] [INFO]- "GET /novels/detail/1111 HTTP/1.1" 200 8273
[2020-10-27 18:24:49,025] [basehttp.py:124] [basehttp:log_message] [INFO]- "GET /novels/add_bookrack?novelUid=1111 HTTP/1.1" 200 17
[2020-10-27 18:24:52,006] [basehttp.py:124] [basehttp:log_message] [INFO]- "GET /novels/show_bookrack HTTP/1.1" 200 6192
[2020-10-27 18:24:54,294] [views.py:23] [views:index] [INFO]- 缓存中的key为：None----浏览器中的key为:c134d966183d11ebb79a5800e3fb0696
[2020-10-27 18:24:54,303] [basehttp.py:124] [basehttp:log_message] [INFO]- "GET /novels/index HTTP/1.1" 302 0
[2020-10-27 18:24:54,316] [basehttp.py:124] [basehttp:log_message] [INFO]- "GET /user/login HTTP/1.1" 200 4227
[2020-10-27 18:24:54,359] [basehttp.py:124] [basehttp:log_message] [INFO]- "GET /user/draw HTTP/1.1" 200 2525
[2020-10-27 18:25:06,180] [basehttp.py:124] [basehttp:log_message] [INFO]- "POST /user/login HTTP/1.1" 200 4341
[2020-10-27 18:25:06,228] [basehttp.py:124] [basehttp:log_message] [INFO]- "GET /user/draw HTTP/1.1" 200 2761
[2020-10-27 18:25:14,627] [basehttp.py:124] [basehttp:log_message] [INFO]- "POST /user/login HTTP/1.1" 302 0
[2020-10-27 18:25:14,641] [views.py:23] [views:index] [INFO]- 缓存中的key为：a78f499e183e11eb9a0f5800e3fb0696----浏览器中的key为:a78f499e183e11eb9a0f5800e3fb0696
[2020-10-27 18:25:14,721] [basehttp.py:124] [basehttp:log_message] [INFO]- "GET /novels/index HTTP/1.1" 200 17963
[2020-10-27 18:25:17,811] [basehttp.py:124] [basehttp:log_message] [INFO]- "GET /novels/detail/121212121212 HTTP/1.1" 200 8634
[2020-10-27 18:25:20,132] [basehttp.py:124] [basehttp:log_message] [INFO]- "GET /novels/add_bookrack?novelUid=121212121212 HTTP/1.1" 200 17
[2020-10-27 18:26:49,184] [basehttp.py:124] [basehttp:log_message] [INFO]- "GET /novels/add_bookrack?novelUid=121212121212 HTTP/1.1" 200 17
[2020-10-27 18:26:52,349] [basehttp.py:124] [basehttp:log_message] [INFO]- "GET /novels/add_bookrack?novelUid=121212121212 HTTP/1.1" 200 17
